root - WARNING - terraceSqMeter was not grabbed.
Traceback (most recent call last):
  File "C:\Osobni\rApp\rApp\acts.py", line 189, in extractData
    dict_offerDetailsAttr[key] = dict_detailsTableOfOffer[value]
KeyError: 'Terasa'
root - WARNING - terrace was not grabbed.
Traceback (most recent call last):
  File "C:\Osobni\rApp\rApp\acts.py", line 189, in extractData
    dict_offerDetailsAttr[key] = dict_detailsTableOfOffer[value]
KeyError: 'Terasa'
root - WARNING - cellarSqMeter was not grabbed.
Traceback (most recent call last):
  File "C:\Osobni\rApp\rApp\acts.py", line 189, in extractData
    dict_offerDetailsAttr[key] = dict_detailsTableOfOffer[value]
KeyError: 'Sklep'
root - WARNING - cellar was not grabbed.
Traceback (most recent call last):
  File "C:\Osobni\rApp\rApp\acts.py", line 189, in extractData
    dict_offerDetailsAttr[key] = dict_detailsTableOfOffer[value]
KeyError: 'Sklep'
root - WARNING - priceNote was not grabbed.
Traceback (most recent call last):
  File "C:\Osobni\rApp\rApp\acts.py", line 189, in extractData
    dict_offerDetailsAttr[key] = dict_detailsTableOfOffer[value]
KeyError: 'Poznámka k cenì'
root - WARNING - location was not grabbed.
Traceback (most recent call last):
  File "C:\Osobni\rApp\rApp\acts.py", line 189, in extractData
    dict_offerDetailsAttr[key] = dict_detailsTableOfOffer[value]
KeyError: 'Umístìní objektu'
root - WARNING - idOrder was not grabbed.
Traceback (most recent call last):
  File "C:\Osobni\rApp\rApp\acts.py", line 189, in extractData
    dict_offerDetailsAttr[key] = dict_detailsTableOfOffer[value]
KeyError: 'ID'
root - WARNING - roads was not grabbed.
Traceback (most recent call last):
  File "C:\Osobni\rApp\rApp\acts.py", line 189, in extractData
    dict_offerDetailsAttr[key] = dict_detailsTableOfOffer[value]
KeyError: 'Komunikace'
root - WARNING - barrieFree was not grabbed.
Traceback (most recent call last):
  File "C:\Osobni\rApp\rApp\acts.py", line 189, in extractData
    dict_offerDetailsAttr[key] = dict_detailsTableOfOffer[value]
KeyError: 'Bezbariérový'
root - WARNING - parking was not grabbed.
Traceback (most recent call last):
  File "C:\Osobni\rApp\rApp\acts.py", line 189, in extractData
    dict_offerDetailsAttr[key] = dict_detailsTableOfOffer[value]
KeyError: 'Parkování'
root - WARNING - garage was not grabbed.
Traceback (most recent call last):
  File "C:\Osobni\rApp\rApp\acts.py", line 189, in extractData
    dict_offerDetailsAttr[key] = dict_detailsTableOfOffer[value]
KeyError: 'Garáž'
root - WARNING - transferToPersonalOwnership was not grabbed.
Traceback (most recent call last):
  File "C:\Osobni\rApp\rApp\acts.py", line 189, in extractData
    dict_offerDetailsAttr[key] = dict_detailsTableOfOffer[value]
KeyError: 'Pøevod do OV'
root - WARNING - yearOfApproval was not grabbed.
Traceback (most recent call last):
  File "C:\Osobni\rApp\rApp\acts.py", line 189, in extractData
    dict_offerDetailsAttr[key] = dict_detailsTableOfOffer[value]
KeyError: 'Rok kolaudace'
root - WARNING - s_water was not grabbed.
Traceback (most recent call last):
  File "C:\Osobni\rApp\rApp\acts.py", line 195, in extractData
    s_transport = dict_detailsTableOfOffer['Doprava'][0]["value"]
KeyError: 'Doprava'
root - WARNING - s_water was not grabbed.
Traceback (most recent call last):
  File "C:\Osobni\rApp\rApp\acts.py", line 201, in extractData
    s_water = dict_detailsTableOfOffer['Voda'][0]["value"]
KeyError: 'Voda'
root - WARNING - s_heating was not grabbed.
Traceback (most recent call last):
  File "C:\Osobni\rApp\rApp\acts.py", line 213, in extractData
    s_heating = dict_detailsTableOfOffer['Topení'][0]["value"]
KeyError: 'Topení'
root - WARNING - s_electricity was not grabbed.
Traceback (most recent call last):
  File "C:\Osobni\rApp\rApp\acts.py", line 225, in extractData
    s_electricity = dict_detailsTableOfOffer['Elektøina'][0]["value"]
KeyError: 'Elektøina'
root - WARNING - culturalHeritageDistance was not grabbed.
Traceback (most recent call last):
  File "C:\Osobni\rApp\rApp\acts.py", line 265, in extractData
    dict_offerDetailsAttr[key] = dict_poi[value]
KeyError: 'Kulturní památka'
root - WARNING - tramDistance was not grabbed.
Traceback (most recent call last):
  File "C:\Osobni\rApp\rApp\acts.py", line 265, in extractData
    dict_offerDetailsAttr[key] = dict_poi[value]
KeyError: 'Tram'
root - WARNING - metroDistance was not grabbed.
Traceback (most recent call last):
  File "C:\Osobni\rApp\rApp\acts.py", line 265, in extractData
    dict_offerDetailsAttr[key] = dict_poi[value]
KeyError: 'Metro'
root - WARNING - naturalAttractionDistance was not grabbed.
Traceback (most recent call last):
  File "C:\Osobni\rApp\rApp\acts.py", line 265, in extractData
    dict_offerDetailsAttr[key] = dict_poi[value]
KeyError: 'Pøírodní zajímavost'
googleapiclient.discovery_cache - WARNING - file_cache is unavailable when using oauth2client >= 4.0.0 or google-auth
Traceback (most recent call last):
  File "C:\Users\pavel\AppData\Local\Programs\Python\Python37-32\lib\site-packages\googleapiclient\discovery_cache\file_cache.py", line 33, in <module>
    from oauth2client.contrib.locked_file import LockedFile
ModuleNotFoundError: No module named 'oauth2client.contrib.locked_file'

During handling of the above exception, another exception occurred:

Traceback (most recent call last):
  File "C:\Users\pavel\AppData\Local\Programs\Python\Python37-32\lib\site-packages\googleapiclient\discovery_cache\file_cache.py", line 37, in <module>
    from oauth2client.locked_file import LockedFile
ModuleNotFoundError: No module named 'oauth2client.locked_file'

During handling of the above exception, another exception occurred:

Traceback (most recent call last):
  File "C:\Users\pavel\AppData\Local\Programs\Python\Python37-32\lib\site-packages\googleapiclient\discovery_cache\__init__.py", line 44, in autodetect
    from . import file_cache
  File "C:\Users\pavel\AppData\Local\Programs\Python\Python37-32\lib\site-packages\googleapiclient\discovery_cache\file_cache.py", line 41, in <module>
    "file_cache is unavailable when using oauth2client >= 4.0.0 or google-auth"
ImportError: file_cache is unavailable when using oauth2client >= 4.0.0 or google-auth
root - WARNING - terraceSqMeter was not grabbed.
Traceback (most recent call last):
  File "C:\Osobni\rApp\rApp\acts.py", line 189, in extractData
    dict_offerDetailsAttr[key] = dict_detailsTableOfOffer[value]
KeyError: 'Terasa'
root - WARNING - terrace was not grabbed.
Traceback (most recent call last):
  File "C:\Osobni\rApp\rApp\acts.py", line 189, in extractData
    dict_offerDetailsAttr[key] = dict_detailsTableOfOffer[value]
KeyError: 'Terasa'
root - WARNING - priceNote was not grabbed.
Traceback (most recent call last):
  File "C:\Osobni\rApp\rApp\acts.py", line 189, in extractData
    dict_offerDetailsAttr[key] = dict_detailsTableOfOffer[value]
KeyError: 'Poznámka k cenì'
root - WARNING - location was not grabbed.
Traceback (most recent call last):
  File "C:\Osobni\rApp\rApp\acts.py", line 189, in extractData
    dict_offerDetailsAttr[key] = dict_detailsTableOfOffer[value]
KeyError: 'Umístìní objektu'
root - WARNING - idOrder was not grabbed.
Traceback (most recent call last):
  File "C:\Osobni\rApp\rApp\acts.py", line 189, in extractData
    dict_offerDetailsAttr[key] = dict_detailsTableOfOffer[value]
KeyError: 'ID'
root - WARNING - energyPerformanceOfBuilding was not grabbed.
Traceback (most recent call last):
  File "C:\Osobni\rApp\rApp\acts.py", line 189, in extractData
    dict_offerDetailsAttr[key] = dict_detailsTableOfOffer[value]
KeyError: 'Energetická nároènost budovy'
root - WARNING - roads was not grabbed.
Traceback (most recent call last):
  File "C:\Osobni\rApp\rApp\acts.py", line 189, in extractData
    dict_offerDetailsAttr[key] = dict_detailsTableOfOffer[value]
KeyError: 'Komunikace'
root - WARNING - barrieFree was not grabbed.
Traceback (most recent call last):
  File "C:\Osobni\rApp\rApp\acts.py", line 189, in extractData
    dict_offerDetailsAttr[key] = dict_detailsTableOfOffer[value]
KeyError: 'Bezbariérový'
root - WARNING - parking was not grabbed.
Traceback (most recent call last):
  File "C:\Osobni\rApp\rApp\acts.py", line 189, in extractData
    dict_offerDetailsAttr[key] = dict_detailsTableOfOffer[value]
KeyError: 'Parkování'
root - WARNING - garage was not grabbed.
Traceback (most recent call last):
  File "C:\Osobni\rApp\rApp\acts.py", line 189, in extractData
    dict_offerDetailsAttr[key] = dict_detailsTableOfOffer[value]
KeyError: 'Garáž'
root - WARNING - transferToPersonalOwnership was not grabbed.
Traceback (most recent call last):
  File "C:\Osobni\rApp\rApp\acts.py", line 189, in extractData
    dict_offerDetailsAttr[key] = dict_detailsTableOfOffer[value]
KeyError: 'Pøevod do OV'
root - WARNING - yearOfApproval was not grabbed.
Traceback (most recent call last):
  File "C:\Osobni\rApp\rApp\acts.py", line 189, in extractData
    dict_offerDetailsAttr[key] = dict_detailsTableOfOffer[value]
KeyError: 'Rok kolaudace'
root - WARNING - s_water was not grabbed.
Traceback (most recent call last):
  File "C:\Osobni\rApp\rApp\acts.py", line 195, in extractData
    s_transport = dict_detailsTableOfOffer['Doprava'][0]["value"]
KeyError: 'Doprava'
root - WARNING - s_gas was not grabbed.
Traceback (most recent call last):
  File "C:\Osobni\rApp\rApp\acts.py", line 207, in extractData
    s_gas = dict_detailsTableOfOffer['Plyn'][0]["value"]
KeyError: 'Plyn'
root - WARNING - culturalHeritageDistance was not grabbed.
Traceback (most recent call last):
  File "C:\Osobni\rApp\rApp\acts.py", line 265, in extractData
    dict_offerDetailsAttr[key] = dict_poi[value]
KeyError: 'Kulturní památka'
root - WARNING - tramDistance was not grabbed.
Traceback (most recent call last):
  File "C:\Osobni\rApp\rApp\acts.py", line 265, in extractData
    dict_offerDetailsAttr[key] = dict_poi[value]
KeyError: 'Tram'
root - WARNING - metroDistance was not grabbed.
Traceback (most recent call last):
  File "C:\Osobni\rApp\rApp\acts.py", line 265, in extractData
    dict_offerDetailsAttr[key] = dict_poi[value]
KeyError: 'Metro'
root - WARNING - cinemaDistance was not grabbed.
Traceback (most recent call last):
  File "C:\Osobni\rApp\rApp\acts.py", line 265, in extractData
    dict_offerDetailsAttr[key] = dict_poi[value]
KeyError: 'Kino'
root - WARNING - naturalAttractionDistance was not grabbed.
Traceback (most recent call last):
  File "C:\Osobni\rApp\rApp\acts.py", line 265, in extractData
    dict_offerDetailsAttr[key] = dict_poi[value]
KeyError: 'Pøírodní zajímavost'
googleapiclient.discovery_cache - WARNING - file_cache is unavailable when using oauth2client >= 4.0.0 or google-auth
Traceback (most recent call last):
  File "C:\Users\pavel\AppData\Local\Programs\Python\Python37-32\lib\site-packages\googleapiclient\discovery_cache\file_cache.py", line 33, in <module>
    from oauth2client.contrib.locked_file import LockedFile
ModuleNotFoundError: No module named 'oauth2client.contrib.locked_file'

During handling of the above exception, another exception occurred:

Traceback (most recent call last):
  File "C:\Users\pavel\AppData\Local\Programs\Python\Python37-32\lib\site-packages\googleapiclient\discovery_cache\file_cache.py", line 37, in <module>
    from oauth2client.locked_file import LockedFile
ModuleNotFoundError: No module named 'oauth2client.locked_file'

During handling of the above exception, another exception occurred:

Traceback (most recent call last):
  File "C:\Users\pavel\AppData\Local\Programs\Python\Python37-32\lib\site-packages\googleapiclient\discovery_cache\__init__.py", line 44, in autodetect
    from . import file_cache
  File "C:\Users\pavel\AppData\Local\Programs\Python\Python37-32\lib\site-packages\googleapiclient\discovery_cache\file_cache.py", line 41, in <module>
    "file_cache is unavailable when using oauth2client >= 4.0.0 or google-auth"
ImportError: file_cache is unavailable when using oauth2client >= 4.0.0 or google-auth
root - WARNING - terraceSqMeter was not grabbed.
Traceback (most recent call last):
  File "C:\Osobni\rApp\rApp\acts.py", line 189, in extractData
    dict_offerDetailsAttr[key] = dict_detailsTableOfOffer[value]
KeyError: 'Terasa'
root - WARNING - terrace was not grabbed.
Traceback (most recent call last):
  File "C:\Osobni\rApp\rApp\acts.py", line 189, in extractData
    dict_offerDetailsAttr[key] = dict_detailsTableOfOffer[value]
KeyError: 'Terasa'
root - WARNING - cellarSqMeter was not grabbed.
Traceback (most recent call last):
  File "C:\Osobni\rApp\rApp\acts.py", line 189, in extractData
    dict_offerDetailsAttr[key] = dict_detailsTableOfOffer[value]
KeyError: 'Sklep'
root - WARNING - cellar was not grabbed.
Traceback (most recent call last):
  File "C:\Osobni\rApp\rApp\acts.py", line 189, in extractData
    dict_offerDetailsAttr[key] = dict_detailsTableOfOffer[value]
KeyError: 'Sklep'
root - WARNING - location was not grabbed.
Traceback (most recent call last):
  File "C:\Osobni\rApp\rApp\acts.py", line 189, in extractData
    dict_offerDetailsAttr[key] = dict_detailsTableOfOffer[value]
KeyError: 'Umístìní objektu'
root - WARNING - idOrder was not grabbed.
Traceback (most recent call last):
  File "C:\Osobni\rApp\rApp\acts.py", line 189, in extractData
    dict_offerDetailsAttr[key] = dict_detailsTableOfOffer[value]
KeyError: 'ID'
root - WARNING - energyPerformanceOfBuilding was not grabbed.
Traceback (most recent call last):
  File "C:\Osobni\rApp\rApp\acts.py", line 189, in extractData
    dict_offerDetailsAttr[key] = dict_detailsTableOfOffer[value]
KeyError: 'Energetická nároènost budovy'
root - WARNING - roads was not grabbed.
Traceback (most recent call last):
  File "C:\Osobni\rApp\rApp\acts.py", line 189, in extractData
    dict_offerDetailsAttr[key] = dict_detailsTableOfOffer[value]
KeyError: 'Komunikace'
root - WARNING - barrieFree was not grabbed.
Traceback (most recent call last):
  File "C:\Osobni\rApp\rApp\acts.py", line 189, in extractData
    dict_offerDetailsAttr[key] = dict_detailsTableOfOffer[value]
KeyError: 'Bezbariérový'
root - WARNING - parking was not grabbed.
Traceback (most recent call last):
  File "C:\Osobni\rApp\rApp\acts.py", line 189, in extractData
    dict_offerDetailsAttr[key] = dict_detailsTableOfOffer[value]
KeyError: 'Parkování'
root - WARNING - garage was not grabbed.
Traceback (most recent call last):
  File "C:\Osobni\rApp\rApp\acts.py", line 189, in extractData
    dict_offerDetailsAttr[key] = dict_detailsTableOfOffer[value]
KeyError: 'Garáž'
root - WARNING - transferToPersonalOwnership was not grabbed.
Traceback (most recent call last):
  File "C:\Osobni\rApp\rApp\acts.py", line 189, in extractData
    dict_offerDetailsAttr[key] = dict_detailsTableOfOffer[value]
KeyError: 'Pøevod do OV'
root - WARNING - yearOfApproval was not grabbed.
Traceback (most recent call last):
  File "C:\Osobni\rApp\rApp\acts.py", line 189, in extractData
    dict_offerDetailsAttr[key] = dict_detailsTableOfOffer[value]
KeyError: 'Rok kolaudace'
root - WARNING - s_water was not grabbed.
Traceback (most recent call last):
  File "C:\Osobni\rApp\rApp\acts.py", line 195, in extractData
    s_transport = dict_detailsTableOfOffer['Doprava'][0]["value"]
KeyError: 'Doprava'
root - WARNING - s_water was not grabbed.
Traceback (most recent call last):
  File "C:\Osobni\rApp\rApp\acts.py", line 201, in extractData
    s_water = dict_detailsTableOfOffer['Voda'][0]["value"]
KeyError: 'Voda'
root - WARNING - s_gas was not grabbed.
Traceback (most recent call last):
  File "C:\Osobni\rApp\rApp\acts.py", line 207, in extractData
    s_gas = dict_detailsTableOfOffer['Plyn'][0]["value"]
KeyError: 'Plyn'
root - WARNING - s_heating was not grabbed.
Traceback (most recent call last):
  File "C:\Osobni\rApp\rApp\acts.py", line 213, in extractData
    s_heating = dict_detailsTableOfOffer['Topení'][0]["value"]
KeyError: 'Topení'
root - WARNING - s_waste was not grabbed.
Traceback (most recent call last):
  File "C:\Osobni\rApp\rApp\acts.py", line 219, in extractData
    s_waste = dict_detailsTableOfOffer['Odpad'][0]["value"]
KeyError: 'Odpad'
root - WARNING - s_electricity was not grabbed.
Traceback (most recent call last):
  File "C:\Osobni\rApp\rApp\acts.py", line 225, in extractData
    s_electricity = dict_detailsTableOfOffer['Elektøina'][0]["value"]
KeyError: 'Elektøina'
root - WARNING - sweetshopDistance was not grabbed.
Traceback (most recent call last):
  File "C:\Osobni\rApp\rApp\acts.py", line 265, in extractData
    dict_offerDetailsAttr[key] = dict_poi[value]
KeyError: 'Cukrárna'
root - WARNING - cinemaDistance was not grabbed.
Traceback (most recent call last):
  File "C:\Osobni\rApp\rApp\acts.py", line 265, in extractData
    dict_offerDetailsAttr[key] = dict_poi[value]
KeyError: 'Kino'
root - WARNING - convenienceStoreDistance was not grabbed.
Traceback (most recent call last):
  File "C:\Osobni\rApp\rApp\acts.py", line 265, in extractData
    dict_offerDetailsAttr[key] = dict_poi[value]
KeyError: 'Veèerka'
root - WARNING - pubDistance was not grabbed.
Traceback (most recent call last):
  File "C:\Osobni\rApp\rApp\acts.py", line 265, in extractData
    dict_offerDetailsAttr[key] = dict_poi[value]
KeyError: 'Hospoda'
root - WARNING - theaterDistance was not grabbed.
Traceback (most recent call last):
  File "C:\Osobni\rApp\rApp\acts.py", line 265, in extractData
    dict_offerDetailsAttr[key] = dict_poi[value]
KeyError: 'Divadlo'
root - WARNING - veterinaryDistance was not grabbed.
Traceback (most recent call last):
  File "C:\Osobni\rApp\rApp\acts.py", line 265, in extractData
    dict_offerDetailsAttr[key] = dict_poi[value]
KeyError: 'Veterináø'
root - WARNING - restaurantDistance was not grabbed.
Traceback (most recent call last):
  File "C:\Osobni\rApp\rApp\acts.py", line 265, in extractData
    dict_offerDetailsAttr[key] = dict_poi[value]
KeyError: 'Restaurace'
root - WARNING - schoolDistance was not grabbed.
Traceback (most recent call last):
  File "C:\Osobni\rApp\rApp\acts.py", line 265, in extractData
    dict_offerDetailsAttr[key] = dict_poi[value]
KeyError: 'Škola'
root - WARNING - postOfficeDistance was not grabbed.
Traceback (most recent call last):
  File "C:\Osobni\rApp\rApp\acts.py", line 265, in extractData
    dict_offerDetailsAttr[key] = dict_poi[value]
KeyError: 'Pošta'
root - WARNING - storeDistance was not grabbed.
Traceback (most recent call last):
  File "C:\Osobni\rApp\rApp\acts.py", line 265, in extractData
    dict_offerDetailsAttr[key] = dict_poi[value]
KeyError: 'Obchod'
root - WARNING - pharmacyDistance was not grabbed.
Traceback (most recent call last):
  File "C:\Osobni\rApp\rApp\acts.py", line 265, in extractData
    dict_offerDetailsAttr[key] = dict_poi[value]
KeyError: 'Lékárna'
root - WARNING - atmDistance was not grabbed.
Traceback (most recent call last):
  File "C:\Osobni\rApp\rApp\acts.py", line 265, in extractData
    dict_offerDetailsAttr[key] = dict_poi[value]
KeyError: 'Bankomat'
root - WARNING - doctorDistance was not grabbed.
Traceback (most recent call last):
  File "C:\Osobni\rApp\rApp\acts.py", line 265, in extractData
    dict_offerDetailsAttr[key] = dict_poi[value]
KeyError: 'Lékaø'
root - WARNING - preSchoolDistance was not grabbed.
Traceback (most recent call last):
  File "C:\Osobni\rApp\rApp\acts.py", line 265, in extractData
    dict_offerDetailsAttr[key] = dict_poi[value]
KeyError: 'Školka'
googleapiclient.discovery_cache - WARNING - file_cache is unavailable when using oauth2client >= 4.0.0 or google-auth
Traceback (most recent call last):
  File "C:\Users\pavel\AppData\Local\Programs\Python\Python37-32\lib\site-packages\googleapiclient\discovery_cache\file_cache.py", line 33, in <module>
    from oauth2client.contrib.locked_file import LockedFile
ModuleNotFoundError: No module named 'oauth2client.contrib.locked_file'

During handling of the above exception, another exception occurred:

Traceback (most recent call last):
  File "C:\Users\pavel\AppData\Local\Programs\Python\Python37-32\lib\site-packages\googleapiclient\discovery_cache\file_cache.py", line 37, in <module>
    from oauth2client.locked_file import LockedFile
ModuleNotFoundError: No module named 'oauth2client.locked_file'

During handling of the above exception, another exception occurred:

Traceback (most recent call last):
  File "C:\Users\pavel\AppData\Local\Programs\Python\Python37-32\lib\site-packages\googleapiclient\discovery_cache\__init__.py", line 44, in autodetect
    from . import file_cache
  File "C:\Users\pavel\AppData\Local\Programs\Python\Python37-32\lib\site-packages\googleapiclient\discovery_cache\file_cache.py", line 41, in <module>
    "file_cache is unavailable when using oauth2client >= 4.0.0 or google-auth"
ImportError: file_cache is unavailable when using oauth2client >= 4.0.0 or google-auth
root - WARNING - terraceSqMeter was not grabbed.
Traceback (most recent call last):
  File "C:\Osobni\rApp\rApp\acts.py", line 189, in extractData
    dict_offerDetailsAttr[key] = dict_detailsTableOfOffer[value]
KeyError: 'Terasa'
root - WARNING - terrace was not grabbed.
Traceback (most recent call last):
  File "C:\Osobni\rApp\rApp\acts.py", line 189, in extractData
    dict_offerDetailsAttr[key] = dict_detailsTableOfOffer[value]
KeyError: 'Terasa'
root - WARNING - cellarSqMeter was not grabbed.
Traceback (most recent call last):
  File "C:\Osobni\rApp\rApp\acts.py", line 189, in extractData
    dict_offerDetailsAttr[key] = dict_detailsTableOfOffer[value]
KeyError: 'Sklep'
root - WARNING - cellar was not grabbed.
Traceback (most recent call last):
  File "C:\Osobni\rApp\rApp\acts.py", line 189, in extractData
    dict_offerDetailsAttr[key] = dict_detailsTableOfOffer[value]
KeyError: 'Sklep'
root - WARNING - location was not grabbed.
Traceback (most recent call last):
  File "C:\Osobni\rApp\rApp\acts.py", line 189, in extractData
    dict_offerDetailsAttr[key] = dict_detailsTableOfOffer[value]
KeyError: 'Umístìní objektu'
root - WARNING - idOrder was not grabbed.
Traceback (most recent call last):
  File "C:\Osobni\rApp\rApp\acts.py", line 189, in extractData
    dict_offerDetailsAttr[key] = dict_detailsTableOfOffer[value]
KeyError: 'ID'
root - WARNING - roads was not grabbed.
Traceback (most recent call last):
  File "C:\Osobni\rApp\rApp\acts.py", line 189, in extractData
    dict_offerDetailsAttr[key] = dict_detailsTableOfOffer[value]
KeyError: 'Komunikace'
root - WARNING - barrieFree was not grabbed.
Traceback (most recent call last):
  File "C:\Osobni\rApp\rApp\acts.py", line 189, in extractData
    dict_offerDetailsAttr[key] = dict_detailsTableOfOffer[value]
KeyError: 'Bezbariérový'
root - WARNING - parking was not grabbed.
Traceback (most recent call last):
  File "C:\Osobni\rApp\rApp\acts.py", line 189, in extractData
    dict_offerDetailsAttr[key] = dict_detailsTableOfOffer[value]
KeyError: 'Parkování'
root - WARNING - garage was not grabbed.
Traceback (most recent call last):
  File "C:\Osobni\rApp\rApp\acts.py", line 189, in extractData
    dict_offerDetailsAttr[key] = dict_detailsTableOfOffer[value]
KeyError: 'Garáž'
root - WARNING - yearOfApproval was not grabbed.
Traceback (most recent call last):
  File "C:\Osobni\rApp\rApp\acts.py", line 189, in extractData
    dict_offerDetailsAttr[key] = dict_detailsTableOfOffer[value]
KeyError: 'Rok kolaudace'
root - WARNING - s_water was not grabbed.
Traceback (most recent call last):
  File "C:\Osobni\rApp\rApp\acts.py", line 195, in extractData
    s_transport = dict_detailsTableOfOffer['Doprava'][0]["value"]
KeyError: 'Doprava'
root - WARNING - s_water was not grabbed.
Traceback (most recent call last):
  File "C:\Osobni\rApp\rApp\acts.py", line 201, in extractData
    s_water = dict_detailsTableOfOffer['Voda'][0]["value"]
KeyError: 'Voda'
root - WARNING - s_heating was not grabbed.
Traceback (most recent call last):
  File "C:\Osobni\rApp\rApp\acts.py", line 213, in extractData
    s_heating = dict_detailsTableOfOffer['Topení'][0]["value"]
KeyError: 'Topení'
root - WARNING - s_electricity was not grabbed.
Traceback (most recent call last):
  File "C:\Osobni\rApp\rApp\acts.py", line 225, in extractData
    s_electricity = dict_detailsTableOfOffer['Elektøina'][0]["value"]
KeyError: 'Elektøina'
root - WARNING - culturalHeritageDistance was not grabbed.
Traceback (most recent call last):
  File "C:\Osobni\rApp\rApp\acts.py", line 265, in extractData
    dict_offerDetailsAttr[key] = dict_poi[value]
KeyError: 'Kulturní památka'
root - WARNING - tramDistance was not grabbed.
Traceback (most recent call last):
  File "C:\Osobni\rApp\rApp\acts.py", line 265, in extractData
    dict_offerDetailsAttr[key] = dict_poi[value]
KeyError: 'Tram'
root - WARNING - metroDistance was not grabbed.
Traceback (most recent call last):
  File "C:\Osobni\rApp\rApp\acts.py", line 265, in extractData
    dict_offerDetailsAttr[key] = dict_poi[value]
KeyError: 'Metro'
root - WARNING - naturalAttractionDistance was not grabbed.
Traceback (most recent call last):
  File "C:\Osobni\rApp\rApp\acts.py", line 265, in extractData
    dict_offerDetailsAttr[key] = dict_poi[value]
KeyError: 'Pøírodní zajímavost'
googleapiclient.discovery_cache - WARNING - file_cache is unavailable when using oauth2client >= 4.0.0 or google-auth
Traceback (most recent call last):
  File "C:\Users\pavel\AppData\Local\Programs\Python\Python37-32\lib\site-packages\googleapiclient\discovery_cache\file_cache.py", line 33, in <module>
    from oauth2client.contrib.locked_file import LockedFile
ModuleNotFoundError: No module named 'oauth2client.contrib.locked_file'

During handling of the above exception, another exception occurred:

Traceback (most recent call last):
  File "C:\Users\pavel\AppData\Local\Programs\Python\Python37-32\lib\site-packages\googleapiclient\discovery_cache\file_cache.py", line 37, in <module>
    from oauth2client.locked_file import LockedFile
ModuleNotFoundError: No module named 'oauth2client.locked_file'

During handling of the above exception, another exception occurred:

Traceback (most recent call last):
  File "C:\Users\pavel\AppData\Local\Programs\Python\Python37-32\lib\site-packages\googleapiclient\discovery_cache\__init__.py", line 44, in autodetect
    from . import file_cache
  File "C:\Users\pavel\AppData\Local\Programs\Python\Python37-32\lib\site-packages\googleapiclient\discovery_cache\file_cache.py", line 41, in <module>
    "file_cache is unavailable when using oauth2client >= 4.0.0 or google-auth"
ImportError: file_cache is unavailable when using oauth2client >= 4.0.0 or google-auth
root - WARNING - terraceSqMeter was not grabbed.
Traceback (most recent call last):
  File "C:\Osobni\rApp\rApp\acts.py", line 189, in extractData
    dict_offerDetailsAttr[key] = dict_detailsTableOfOffer[value]
KeyError: 'Terasa'
root - WARNING - terrace was not grabbed.
Traceback (most recent call last):
  File "C:\Osobni\rApp\rApp\acts.py", line 189, in extractData
    dict_offerDetailsAttr[key] = dict_detailsTableOfOffer[value]
KeyError: 'Terasa'
root - WARNING - cellarSqMeter was not grabbed.
Traceback (most recent call last):
  File "C:\Osobni\rApp\rApp\acts.py", line 189, in extractData
    dict_offerDetailsAttr[key] = dict_detailsTableOfOffer[value]
KeyError: 'Sklep'
root - WARNING - cellar was not grabbed.
Traceback (most recent call last):
  File "C:\Osobni\rApp\rApp\acts.py", line 189, in extractData
    dict_offerDetailsAttr[key] = dict_detailsTableOfOffer[value]
KeyError: 'Sklep'
root - WARNING - priceNote was not grabbed.
Traceback (most recent call last):
  File "C:\Osobni\rApp\rApp\acts.py", line 189, in extractData
    dict_offerDetailsAttr[key] = dict_detailsTableOfOffer[value]
KeyError: 'Poznámka k cenì'
root - WARNING - location was not grabbed.
Traceback (most recent call last):
  File "C:\Osobni\rApp\rApp\acts.py", line 189, in extractData
    dict_offerDetailsAttr[key] = dict_detailsTableOfOffer[value]
KeyError: 'Umístìní objektu'
root - WARNING - idOrder was not grabbed.
Traceback (most recent call last):
  File "C:\Osobni\rApp\rApp\acts.py", line 189, in extractData
    dict_offerDetailsAttr[key] = dict_detailsTableOfOffer[value]
KeyError: 'ID'
root - WARNING - roads was not grabbed.
Traceback (most recent call last):
  File "C:\Osobni\rApp\rApp\acts.py", line 189, in extractData
    dict_offerDetailsAttr[key] = dict_detailsTableOfOffer[value]
KeyError: 'Komunikace'
root - WARNING - barrieFree was not grabbed.
Traceback (most recent call last):
  File "C:\Osobni\rApp\rApp\acts.py", line 189, in extractData
    dict_offerDetailsAttr[key] = dict_detailsTableOfOffer[value]
KeyError: 'Bezbariérový'
root - WARNING - parking was not grabbed.
Traceback (most recent call last):
  File "C:\Osobni\rApp\rApp\acts.py", line 189, in extractData
    dict_offerDetailsAttr[key] = dict_detailsTableOfOffer[value]
KeyError: 'Parkování'
root - WARNING - garage was not grabbed.
Traceback (most recent call last):
  File "C:\Osobni\rApp\rApp\acts.py", line 189, in extractData
    dict_offerDetailsAttr[key] = dict_detailsTableOfOffer[value]
KeyError: 'Garáž'
root - WARNING - yearOfApproval was not grabbed.
Traceback (most recent call last):
  File "C:\Osobni\rApp\rApp\acts.py", line 189, in extractData
    dict_offerDetailsAttr[key] = dict_detailsTableOfOffer[value]
KeyError: 'Rok kolaudace'
root - WARNING - s_water was not grabbed.
Traceback (most recent call last):
  File "C:\Osobni\rApp\rApp\acts.py", line 195, in extractData
    s_transport = dict_detailsTableOfOffer['Doprava'][0]["value"]
KeyError: 'Doprava'
root - WARNING - s_heating was not grabbed.
Traceback (most recent call last):
  File "C:\Osobni\rApp\rApp\acts.py", line 213, in extractData
    s_heating = dict_detailsTableOfOffer['Topení'][0]["value"]
KeyError: 'Topení'
root - WARNING - culturalHeritageDistance was not grabbed.
Traceback (most recent call last):
  File "C:\Osobni\rApp\rApp\acts.py", line 265, in extractData
    dict_offerDetailsAttr[key] = dict_poi[value]
KeyError: 'Kulturní památka'
root - WARNING - tramDistance was not grabbed.
Traceback (most recent call last):
  File "C:\Osobni\rApp\rApp\acts.py", line 265, in extractData
    dict_offerDetailsAttr[key] = dict_poi[value]
KeyError: 'Tram'
root - WARNING - metroDistance was not grabbed.
Traceback (most recent call last):
  File "C:\Osobni\rApp\rApp\acts.py", line 265, in extractData
    dict_offerDetailsAttr[key] = dict_poi[value]
KeyError: 'Metro'
root - WARNING - naturalAttractionDistance was not grabbed.
Traceback (most recent call last):
  File "C:\Osobni\rApp\rApp\acts.py", line 265, in extractData
    dict_offerDetailsAttr[key] = dict_poi[value]
KeyError: 'Pøírodní zajímavost'
googleapiclient.discovery_cache - WARNING - file_cache is unavailable when using oauth2client >= 4.0.0 or google-auth
Traceback (most recent call last):
  File "C:\Users\pavel\AppData\Local\Programs\Python\Python37-32\lib\site-packages\googleapiclient\discovery_cache\file_cache.py", line 33, in <module>
    from oauth2client.contrib.locked_file import LockedFile
ModuleNotFoundError: No module named 'oauth2client.contrib.locked_file'

During handling of the above exception, another exception occurred:

Traceback (most recent call last):
  File "C:\Users\pavel\AppData\Local\Programs\Python\Python37-32\lib\site-packages\googleapiclient\discovery_cache\file_cache.py", line 37, in <module>
    from oauth2client.locked_file import LockedFile
ModuleNotFoundError: No module named 'oauth2client.locked_file'

During handling of the above exception, another exception occurred:

Traceback (most recent call last):
  File "C:\Users\pavel\AppData\Local\Programs\Python\Python37-32\lib\site-packages\googleapiclient\discovery_cache\__init__.py", line 44, in autodetect
    from . import file_cache
  File "C:\Users\pavel\AppData\Local\Programs\Python\Python37-32\lib\site-packages\googleapiclient\discovery_cache\file_cache.py", line 41, in <module>
    "file_cache is unavailable when using oauth2client >= 4.0.0 or google-auth"
ImportError: file_cache is unavailable when using oauth2client >= 4.0.0 or google-auth
root - WARNING - terraceSqMeter was not grabbed.
Traceback (most recent call last):
  File "C:\Osobni\rApp\rApp\acts.py", line 189, in extractData
    dict_offerDetailsAttr[key] = dict_detailsTableOfOffer[value]
KeyError: 'Terasa'
root - WARNING - terrace was not grabbed.
Traceback (most recent call last):
  File "C:\Osobni\rApp\rApp\acts.py", line 189, in extractData
    dict_offerDetailsAttr[key] = dict_detailsTableOfOffer[value]
KeyError: 'Terasa'
root - WARNING - cellarSqMeter was not grabbed.
Traceback (most recent call last):
  File "C:\Osobni\rApp\rApp\acts.py", line 189, in extractData
    dict_offerDetailsAttr[key] = dict_detailsTableOfOffer[value]
KeyError: 'Sklep'
root - WARNING - cellar was not grabbed.
Traceback (most recent call last):
  File "C:\Osobni\rApp\rApp\acts.py", line 189, in extractData
    dict_offerDetailsAttr[key] = dict_detailsTableOfOffer[value]
KeyError: 'Sklep'
root - WARNING - location was not grabbed.
Traceback (most recent call last):
  File "C:\Osobni\rApp\rApp\acts.py", line 189, in extractData
    dict_offerDetailsAttr[key] = dict_detailsTableOfOffer[value]
KeyError: 'Umístìní objektu'
root - WARNING - idOrder was not grabbed.
Traceback (most recent call last):
  File "C:\Osobni\rApp\rApp\acts.py", line 189, in extractData
    dict_offerDetailsAttr[key] = dict_detailsTableOfOffer[value]
KeyError: 'ID'
root - WARNING - roads was not grabbed.
Traceback (most recent call last):
  File "C:\Osobni\rApp\rApp\acts.py", line 189, in extractData
    dict_offerDetailsAttr[key] = dict_detailsTableOfOffer[value]
KeyError: 'Komunikace'
root - WARNING - barrieFree was not grabbed.
Traceback (most recent call last):
  File "C:\Osobni\rApp\rApp\acts.py", line 189, in extractData
    dict_offerDetailsAttr[key] = dict_detailsTableOfOffer[value]
KeyError: 'Bezbariérový'
root - WARNING - parking was not grabbed.
Traceback (most recent call last):
  File "C:\Osobni\rApp\rApp\acts.py", line 189, in extractData
    dict_offerDetailsAttr[key] = dict_detailsTableOfOffer[value]
KeyError: 'Parkování'
root - WARNING - garage was not grabbed.
Traceback (most recent call last):
  File "C:\Osobni\rApp\rApp\acts.py", line 189, in extractData
    dict_offerDetailsAttr[key] = dict_detailsTableOfOffer[value]
KeyError: 'Garáž'
root - WARNING - yearOfApproval was not grabbed.
Traceback (most recent call last):
  File "C:\Osobni\rApp\rApp\acts.py", line 189, in extractData
    dict_offerDetailsAttr[key] = dict_detailsTableOfOffer[value]
KeyError: 'Rok kolaudace'
root - WARNING - s_water was not grabbed.
Traceback (most recent call last):
  File "C:\Osobni\rApp\rApp\acts.py", line 195, in extractData
    s_transport = dict_detailsTableOfOffer['Doprava'][0]["value"]
KeyError: 'Doprava'
root - WARNING - s_water was not grabbed.
Traceback (most recent call last):
  File "C:\Osobni\rApp\rApp\acts.py", line 201, in extractData
    s_water = dict_detailsTableOfOffer['Voda'][0]["value"]
KeyError: 'Voda'
root - WARNING - s_heating was not grabbed.
Traceback (most recent call last):
  File "C:\Osobni\rApp\rApp\acts.py", line 213, in extractData
    s_heating = dict_detailsTableOfOffer['Topení'][0]["value"]
KeyError: 'Topení'
root - WARNING - s_electricity was not grabbed.
Traceback (most recent call last):
  File "C:\Osobni\rApp\rApp\acts.py", line 225, in extractData
    s_electricity = dict_detailsTableOfOffer['Elektøina'][0]["value"]
KeyError: 'Elektøina'
root - WARNING - culturalHeritageDistance was not grabbed.
Traceback (most recent call last):
  File "C:\Osobni\rApp\rApp\acts.py", line 265, in extractData
    dict_offerDetailsAttr[key] = dict_poi[value]
KeyError: 'Kulturní památka'
root - WARNING - tramDistance was not grabbed.
Traceback (most recent call last):
  File "C:\Osobni\rApp\rApp\acts.py", line 265, in extractData
    dict_offerDetailsAttr[key] = dict_poi[value]
KeyError: 'Tram'
root - WARNING - metroDistance was not grabbed.
Traceback (most recent call last):
  File "C:\Osobni\rApp\rApp\acts.py", line 265, in extractData
    dict_offerDetailsAttr[key] = dict_poi[value]
KeyError: 'Metro'
root - WARNING - naturalAttractionDistance was not grabbed.
Traceback (most recent call last):
  File "C:\Osobni\rApp\rApp\acts.py", line 265, in extractData
    dict_offerDetailsAttr[key] = dict_poi[value]
KeyError: 'Pøírodní zajímavost'
googleapiclient.discovery_cache - WARNING - file_cache is unavailable when using oauth2client >= 4.0.0 or google-auth
Traceback (most recent call last):
  File "C:\Users\pavel\AppData\Local\Programs\Python\Python37-32\lib\site-packages\googleapiclient\discovery_cache\file_cache.py", line 33, in <module>
    from oauth2client.contrib.locked_file import LockedFile
ModuleNotFoundError: No module named 'oauth2client.contrib.locked_file'

During handling of the above exception, another exception occurred:

Traceback (most recent call last):
  File "C:\Users\pavel\AppData\Local\Programs\Python\Python37-32\lib\site-packages\googleapiclient\discovery_cache\file_cache.py", line 37, in <module>
    from oauth2client.locked_file import LockedFile
ModuleNotFoundError: No module named 'oauth2client.locked_file'

During handling of the above exception, another exception occurred:

Traceback (most recent call last):
  File "C:\Users\pavel\AppData\Local\Programs\Python\Python37-32\lib\site-packages\googleapiclient\discovery_cache\__init__.py", line 44, in autodetect
    from . import file_cache
  File "C:\Users\pavel\AppData\Local\Programs\Python\Python37-32\lib\site-packages\googleapiclient\discovery_cache\file_cache.py", line 41, in <module>
    "file_cache is unavailable when using oauth2client >= 4.0.0 or google-auth"
ImportError: file_cache is unavailable when using oauth2client >= 4.0.0 or google-auth
root - WARNING - terraceSqMeter was not grabbed.
Traceback (most recent call last):
  File "C:\Osobni\rApp\rApp\acts.py", line 189, in extractData
    dict_offerDetailsAttr[key] = dict_detailsTableOfOffer[value]
KeyError: 'Terasa'
root - WARNING - terrace was not grabbed.
Traceback (most recent call last):
  File "C:\Osobni\rApp\rApp\acts.py", line 189, in extractData
    dict_offerDetailsAttr[key] = dict_detailsTableOfOffer[value]
KeyError: 'Terasa'
root - WARNING - cellarSqMeter was not grabbed.
Traceback (most recent call last):
  File "C:\Osobni\rApp\rApp\acts.py", line 189, in extractData
    dict_offerDetailsAttr[key] = dict_detailsTableOfOffer[value]
KeyError: 'Sklep'
root - WARNING - cellar was not grabbed.
Traceback (most recent call last):
  File "C:\Osobni\rApp\rApp\acts.py", line 189, in extractData
    dict_offerDetailsAttr[key] = dict_detailsTableOfOffer[value]
KeyError: 'Sklep'
root - WARNING - priceNote was not grabbed.
Traceback (most recent call last):
  File "C:\Osobni\rApp\rApp\acts.py", line 189, in extractData
    dict_offerDetailsAttr[key] = dict_detailsTableOfOffer[value]
KeyError: 'Poznámka k cenì'
root - WARNING - location was not grabbed.
Traceback (most recent call last):
  File "C:\Osobni\rApp\rApp\acts.py", line 189, in extractData
    dict_offerDetailsAttr[key] = dict_detailsTableOfOffer[value]
KeyError: 'Umístìní objektu'
root - WARNING - idOrder was not grabbed.
Traceback (most recent call last):
  File "C:\Osobni\rApp\rApp\acts.py", line 189, in extractData
    dict_offerDetailsAttr[key] = dict_detailsTableOfOffer[value]
KeyError: 'ID'
root - WARNING - roads was not grabbed.
Traceback (most recent call last):
  File "C:\Osobni\rApp\rApp\acts.py", line 189, in extractData
    dict_offerDetailsAttr[key] = dict_detailsTableOfOffer[value]
KeyError: 'Komunikace'
root - WARNING - barrieFree was not grabbed.
Traceback (most recent call last):
  File "C:\Osobni\rApp\rApp\acts.py", line 189, in extractData
    dict_offerDetailsAttr[key] = dict_detailsTableOfOffer[value]
KeyError: 'Bezbariérový'
root - WARNING - parking was not grabbed.
Traceback (most recent call last):
  File "C:\Osobni\rApp\rApp\acts.py", line 189, in extractData
    dict_offerDetailsAttr[key] = dict_detailsTableOfOffer[value]
KeyError: 'Parkování'
root - WARNING - garage was not grabbed.
Traceback (most recent call last):
  File "C:\Osobni\rApp\rApp\acts.py", line 189, in extractData
    dict_offerDetailsAttr[key] = dict_detailsTableOfOffer[value]
KeyError: 'Garáž'
root - WARNING - transferToPersonalOwnership was not grabbed.
Traceback (most recent call last):
  File "C:\Osobni\rApp\rApp\acts.py", line 189, in extractData
    dict_offerDetailsAttr[key] = dict_detailsTableOfOffer[value]
KeyError: 'Pøevod do OV'
root - WARNING - yearOfApproval was not grabbed.
Traceback (most recent call last):
  File "C:\Osobni\rApp\rApp\acts.py", line 189, in extractData
    dict_offerDetailsAttr[key] = dict_detailsTableOfOffer[value]
KeyError: 'Rok kolaudace'
root - WARNING - s_water was not grabbed.
Traceback (most recent call last):
  File "C:\Osobni\rApp\rApp\acts.py", line 195, in extractData
    s_transport = dict_detailsTableOfOffer['Doprava'][0]["value"]
KeyError: 'Doprava'
root - WARNING - s_water was not grabbed.
Traceback (most recent call last):
  File "C:\Osobni\rApp\rApp\acts.py", line 201, in extractData
    s_water = dict_detailsTableOfOffer['Voda'][0]["value"]
KeyError: 'Voda'
root - WARNING - s_heating was not grabbed.
Traceback (most recent call last):
  File "C:\Osobni\rApp\rApp\acts.py", line 213, in extractData
    s_heating = dict_detailsTableOfOffer['Topení'][0]["value"]
KeyError: 'Topení'
root - WARNING - s_electricity was not grabbed.
Traceback (most recent call last):
  File "C:\Osobni\rApp\rApp\acts.py", line 225, in extractData
    s_electricity = dict_detailsTableOfOffer['Elektøina'][0]["value"]
KeyError: 'Elektøina'
root - WARNING - culturalHeritageDistance was not grabbed.
Traceback (most recent call last):
  File "C:\Osobni\rApp\rApp\acts.py", line 265, in extractData
    dict_offerDetailsAttr[key] = dict_poi[value]
KeyError: 'Kulturní památka'
root - WARNING - tramDistance was not grabbed.
Traceback (most recent call last):
  File "C:\Osobni\rApp\rApp\acts.py", line 265, in extractData
    dict_offerDetailsAttr[key] = dict_poi[value]
KeyError: 'Tram'
root - WARNING - metroDistance was not grabbed.
Traceback (most recent call last):
  File "C:\Osobni\rApp\rApp\acts.py", line 265, in extractData
    dict_offerDetailsAttr[key] = dict_poi[value]
KeyError: 'Metro'
root - WARNING - naturalAttractionDistance was not grabbed.
Traceback (most recent call last):
  File "C:\Osobni\rApp\rApp\acts.py", line 265, in extractData
    dict_offerDetailsAttr[key] = dict_poi[value]
KeyError: 'Pøírodní zajímavost'
googleapiclient.discovery_cache - WARNING - file_cache is unavailable when using oauth2client >= 4.0.0 or google-auth
Traceback (most recent call last):
  File "C:\Users\pavel\AppData\Local\Programs\Python\Python37-32\lib\site-packages\googleapiclient\discovery_cache\file_cache.py", line 33, in <module>
    from oauth2client.contrib.locked_file import LockedFile
ModuleNotFoundError: No module named 'oauth2client.contrib.locked_file'

During handling of the above exception, another exception occurred:

Traceback (most recent call last):
  File "C:\Users\pavel\AppData\Local\Programs\Python\Python37-32\lib\site-packages\googleapiclient\discovery_cache\file_cache.py", line 37, in <module>
    from oauth2client.locked_file import LockedFile
ModuleNotFoundError: No module named 'oauth2client.locked_file'

During handling of the above exception, another exception occurred:

Traceback (most recent call last):
  File "C:\Users\pavel\AppData\Local\Programs\Python\Python37-32\lib\site-packages\googleapiclient\discovery_cache\__init__.py", line 44, in autodetect
    from . import file_cache
  File "C:\Users\pavel\AppData\Local\Programs\Python\Python37-32\lib\site-packages\googleapiclient\discovery_cache\file_cache.py", line 41, in <module>
    "file_cache is unavailable when using oauth2client >= 4.0.0 or google-auth"
ImportError: file_cache is unavailable when using oauth2client >= 4.0.0 or google-auth
root - WARNING - terraceSqMeter was not grabbed.
Traceback (most recent call last):
  File "C:\Osobni\rApp\rApp\acts.py", line 189, in extractData
    dict_offerDetailsAttr[key] = dict_detailsTableOfOffer[value]
KeyError: 'Terasa'
root - WARNING - terrace was not grabbed.
Traceback (most recent call last):
  File "C:\Osobni\rApp\rApp\acts.py", line 189, in extractData
    dict_offerDetailsAttr[key] = dict_detailsTableOfOffer[value]
KeyError: 'Terasa'
root - WARNING - idOrder was not grabbed.
Traceback (most recent call last):
  File "C:\Osobni\rApp\rApp\acts.py", line 189, in extractData
    dict_offerDetailsAttr[key] = dict_detailsTableOfOffer[value]
KeyError: 'ID'
root - WARNING - roads was not grabbed.
Traceback (most recent call last):
  File "C:\Osobni\rApp\rApp\acts.py", line 189, in extractData
    dict_offerDetailsAttr[key] = dict_detailsTableOfOffer[value]
KeyError: 'Komunikace'
root - WARNING - barrieFree was not grabbed.
Traceback (most recent call last):
  File "C:\Osobni\rApp\rApp\acts.py", line 189, in extractData
    dict_offerDetailsAttr[key] = dict_detailsTableOfOffer[value]
KeyError: 'Bezbariérový'
root - WARNING - garage was not grabbed.
Traceback (most recent call last):
  File "C:\Osobni\rApp\rApp\acts.py", line 189, in extractData
    dict_offerDetailsAttr[key] = dict_detailsTableOfOffer[value]
KeyError: 'Garáž'
root - WARNING - equipped was not grabbed.
Traceback (most recent call last):
  File "C:\Osobni\rApp\rApp\acts.py", line 189, in extractData
    dict_offerDetailsAttr[key] = dict_detailsTableOfOffer[value]
KeyError: 'Vybavení'
root - WARNING - transferToPersonalOwnership was not grabbed.
Traceback (most recent call last):
  File "C:\Osobni\rApp\rApp\acts.py", line 189, in extractData
    dict_offerDetailsAttr[key] = dict_detailsTableOfOffer[value]
KeyError: 'Pøevod do OV'
root - WARNING - yearOfApproval was not grabbed.
Traceback (most recent call last):
  File "C:\Osobni\rApp\rApp\acts.py", line 189, in extractData
    dict_offerDetailsAttr[key] = dict_detailsTableOfOffer[value]
KeyError: 'Rok kolaudace'
root - WARNING - s_gas was not grabbed.
Traceback (most recent call last):
  File "C:\Osobni\rApp\rApp\acts.py", line 207, in extractData
    s_gas = dict_detailsTableOfOffer['Plyn'][0]["value"]
KeyError: 'Plyn'
root - WARNING - culturalHeritageDistance was not grabbed.
Traceback (most recent call last):
  File "C:\Osobni\rApp\rApp\acts.py", line 265, in extractData
    dict_offerDetailsAttr[key] = dict_poi[value]
KeyError: 'Kulturní památka'
root - WARNING - tramDistance was not grabbed.
Traceback (most recent call last):
  File "C:\Osobni\rApp\rApp\acts.py", line 265, in extractData
    dict_offerDetailsAttr[key] = dict_poi[value]
KeyError: 'Tram'
root - WARNING - naturalAttractionDistance was not grabbed.
Traceback (most recent call last):
  File "C:\Osobni\rApp\rApp\acts.py", line 265, in extractData
    dict_offerDetailsAttr[key] = dict_poi[value]
KeyError: 'Pøírodní zajímavost'
googleapiclient.discovery_cache - WARNING - file_cache is unavailable when using oauth2client >= 4.0.0 or google-auth
Traceback (most recent call last):
  File "C:\Users\pavel\AppData\Local\Programs\Python\Python37-32\lib\site-packages\googleapiclient\discovery_cache\file_cache.py", line 33, in <module>
    from oauth2client.contrib.locked_file import LockedFile
ModuleNotFoundError: No module named 'oauth2client.contrib.locked_file'

During handling of the above exception, another exception occurred:

Traceback (most recent call last):
  File "C:\Users\pavel\AppData\Local\Programs\Python\Python37-32\lib\site-packages\googleapiclient\discovery_cache\file_cache.py", line 37, in <module>
    from oauth2client.locked_file import LockedFile
ModuleNotFoundError: No module named 'oauth2client.locked_file'

During handling of the above exception, another exception occurred:

Traceback (most recent call last):
  File "C:\Users\pavel\AppData\Local\Programs\Python\Python37-32\lib\site-packages\googleapiclient\discovery_cache\__init__.py", line 44, in autodetect
    from . import file_cache
  File "C:\Users\pavel\AppData\Local\Programs\Python\Python37-32\lib\site-packages\googleapiclient\discovery_cache\file_cache.py", line 41, in <module>
    "file_cache is unavailable when using oauth2client >= 4.0.0 or google-auth"
ImportError: file_cache is unavailable when using oauth2client >= 4.0.0 or google-auth
root - WARNING - terraceSqMeter was not grabbed.
Traceback (most recent call last):
  File "C:\Osobni\rApp\rApp\acts.py", line 189, in extractData
    dict_offerDetailsAttr[key] = dict_detailsTableOfOffer[value]
KeyError: 'Terasa'
root - WARNING - terrace was not grabbed.
Traceback (most recent call last):
  File "C:\Osobni\rApp\rApp\acts.py", line 189, in extractData
    dict_offerDetailsAttr[key] = dict_detailsTableOfOffer[value]
KeyError: 'Terasa'
root - WARNING - cellarSqMeter was not grabbed.
Traceback (most recent call last):
  File "C:\Osobni\rApp\rApp\acts.py", line 189, in extractData
    dict_offerDetailsAttr[key] = dict_detailsTableOfOffer[value]
KeyError: 'Sklep'
root - WARNING - cellar was not grabbed.
Traceback (most recent call last):
  File "C:\Osobni\rApp\rApp\acts.py", line 189, in extractData
    dict_offerDetailsAttr[key] = dict_detailsTableOfOffer[value]
KeyError: 'Sklep'
root - WARNING - priceNote was not grabbed.
Traceback (most recent call last):
  File "C:\Osobni\rApp\rApp\acts.py", line 189, in extractData
    dict_offerDetailsAttr[key] = dict_detailsTableOfOffer[value]
KeyError: 'Poznámka k cenì'
root - WARNING - location was not grabbed.
Traceback (most recent call last):
  File "C:\Osobni\rApp\rApp\acts.py", line 189, in extractData
    dict_offerDetailsAttr[key] = dict_detailsTableOfOffer[value]
KeyError: 'Umístìní objektu'
root - WARNING - lift was not grabbed.
Traceback (most recent call last):
  File "C:\Osobni\rApp\rApp\acts.py", line 189, in extractData
    dict_offerDetailsAttr[key] = dict_detailsTableOfOffer[value]
KeyError: 'Výtah'
root - WARNING - idOrder was not grabbed.
Traceback (most recent call last):
  File "C:\Osobni\rApp\rApp\acts.py", line 189, in extractData
    dict_offerDetailsAttr[key] = dict_detailsTableOfOffer[value]
KeyError: 'ID'
root - WARNING - roads was not grabbed.
Traceback (most recent call last):
  File "C:\Osobni\rApp\rApp\acts.py", line 189, in extractData
    dict_offerDetailsAttr[key] = dict_detailsTableOfOffer[value]
KeyError: 'Komunikace'
root - WARNING - barrieFree was not grabbed.
Traceback (most recent call last):
  File "C:\Osobni\rApp\rApp\acts.py", line 189, in extractData
    dict_offerDetailsAttr[key] = dict_detailsTableOfOffer[value]
KeyError: 'Bezbariérový'
root - WARNING - parking was not grabbed.
Traceback (most recent call last):
  File "C:\Osobni\rApp\rApp\acts.py", line 189, in extractData
    dict_offerDetailsAttr[key] = dict_detailsTableOfOffer[value]
KeyError: 'Parkování'
root - WARNING - garage was not grabbed.
Traceback (most recent call last):
  File "C:\Osobni\rApp\rApp\acts.py", line 189, in extractData
    dict_offerDetailsAttr[key] = dict_detailsTableOfOffer[value]
KeyError: 'Garáž'
root - WARNING - transferToPersonalOwnership was not grabbed.
Traceback (most recent call last):
  File "C:\Osobni\rApp\rApp\acts.py", line 189, in extractData
    dict_offerDetailsAttr[key] = dict_detailsTableOfOffer[value]
KeyError: 'Pøevod do OV'
root - WARNING - yearOfApproval was not grabbed.
Traceback (most recent call last):
  File "C:\Osobni\rApp\rApp\acts.py", line 189, in extractData
    dict_offerDetailsAttr[key] = dict_detailsTableOfOffer[value]
KeyError: 'Rok kolaudace'
root - WARNING - s_water was not grabbed.
Traceback (most recent call last):
  File "C:\Osobni\rApp\rApp\acts.py", line 195, in extractData
    s_transport = dict_detailsTableOfOffer['Doprava'][0]["value"]
KeyError: 'Doprava'
root - WARNING - s_water was not grabbed.
Traceback (most recent call last):
  File "C:\Osobni\rApp\rApp\acts.py", line 201, in extractData
    s_water = dict_detailsTableOfOffer['Voda'][0]["value"]
KeyError: 'Voda'
root - WARNING - s_heating was not grabbed.
Traceback (most recent call last):
  File "C:\Osobni\rApp\rApp\acts.py", line 213, in extractData
    s_heating = dict_detailsTableOfOffer['Topení'][0]["value"]
KeyError: 'Topení'
root - WARNING - s_electricity was not grabbed.
Traceback (most recent call last):
  File "C:\Osobni\rApp\rApp\acts.py", line 225, in extractData
    s_electricity = dict_detailsTableOfOffer['Elektøina'][0]["value"]
KeyError: 'Elektøina'
root - WARNING - culturalHeritageDistance was not grabbed.
Traceback (most recent call last):
  File "C:\Osobni\rApp\rApp\acts.py", line 265, in extractData
    dict_offerDetailsAttr[key] = dict_poi[value]
KeyError: 'Kulturní památka'
root - WARNING - tramDistance was not grabbed.
Traceback (most recent call last):
  File "C:\Osobni\rApp\rApp\acts.py", line 265, in extractData
    dict_offerDetailsAttr[key] = dict_poi[value]
KeyError: 'Tram'
root - WARNING - metroDistance was not grabbed.
Traceback (most recent call last):
  File "C:\Osobni\rApp\rApp\acts.py", line 265, in extractData
    dict_offerDetailsAttr[key] = dict_poi[value]
KeyError: 'Metro'
root - WARNING - naturalAttractionDistance was not grabbed.
Traceback (most recent call last):
  File "C:\Osobni\rApp\rApp\acts.py", line 265, in extractData
    dict_offerDetailsAttr[key] = dict_poi[value]
KeyError: 'Pøírodní zajímavost'
googleapiclient.discovery_cache - WARNING - file_cache is unavailable when using oauth2client >= 4.0.0 or google-auth
Traceback (most recent call last):
  File "C:\Users\pavel\AppData\Local\Programs\Python\Python37-32\lib\site-packages\googleapiclient\discovery_cache\file_cache.py", line 33, in <module>
    from oauth2client.contrib.locked_file import LockedFile
ModuleNotFoundError: No module named 'oauth2client.contrib.locked_file'

During handling of the above exception, another exception occurred:

Traceback (most recent call last):
  File "C:\Users\pavel\AppData\Local\Programs\Python\Python37-32\lib\site-packages\googleapiclient\discovery_cache\file_cache.py", line 37, in <module>
    from oauth2client.locked_file import LockedFile
ModuleNotFoundError: No module named 'oauth2client.locked_file'

During handling of the above exception, another exception occurred:

Traceback (most recent call last):
  File "C:\Users\pavel\AppData\Local\Programs\Python\Python37-32\lib\site-packages\googleapiclient\discovery_cache\__init__.py", line 44, in autodetect
    from . import file_cache
  File "C:\Users\pavel\AppData\Local\Programs\Python\Python37-32\lib\site-packages\googleapiclient\discovery_cache\file_cache.py", line 41, in <module>
    "file_cache is unavailable when using oauth2client >= 4.0.0 or google-auth"
ImportError: file_cache is unavailable when using oauth2client >= 4.0.0 or google-auth
root - WARNING - terraceSqMeter was not grabbed.
Traceback (most recent call last):
  File "C:\Osobni\rApp\rApp\acts.py", line 189, in extractData
    dict_offerDetailsAttr[key] = dict_detailsTableOfOffer[value]
KeyError: 'Terasa'
root - WARNING - terrace was not grabbed.
Traceback (most recent call last):
  File "C:\Osobni\rApp\rApp\acts.py", line 189, in extractData
    dict_offerDetailsAttr[key] = dict_detailsTableOfOffer[value]
KeyError: 'Terasa'
root - WARNING - priceNote was not grabbed.
Traceback (most recent call last):
  File "C:\Osobni\rApp\rApp\acts.py", line 189, in extractData
    dict_offerDetailsAttr[key] = dict_detailsTableOfOffer[value]
KeyError: 'Poznámka k cenì'
root - WARNING - id was not grabbed.
Traceback (most recent call last):
  File "C:\Osobni\rApp\rApp\acts.py", line 189, in extractData
    dict_offerDetailsAttr[key] = dict_detailsTableOfOffer[value]
KeyError: 'ID zakázky'
root - WARNING - energyPerformanceOfBuilding was not grabbed.
Traceback (most recent call last):
  File "C:\Osobni\rApp\rApp\acts.py", line 189, in extractData
    dict_offerDetailsAttr[key] = dict_detailsTableOfOffer[value]
KeyError: 'Energetická nároènost budovy'
root - WARNING - parking was not grabbed.
Traceback (most recent call last):
  File "C:\Osobni\rApp\rApp\acts.py", line 189, in extractData
    dict_offerDetailsAttr[key] = dict_detailsTableOfOffer[value]
KeyError: 'Parkování'
root - WARNING - garage was not grabbed.
Traceback (most recent call last):
  File "C:\Osobni\rApp\rApp\acts.py", line 189, in extractData
    dict_offerDetailsAttr[key] = dict_detailsTableOfOffer[value]
KeyError: 'Garáž'
root - WARNING - transferToPersonalOwnership was not grabbed.
Traceback (most recent call last):
  File "C:\Osobni\rApp\rApp\acts.py", line 189, in extractData
    dict_offerDetailsAttr[key] = dict_detailsTableOfOffer[value]
KeyError: 'Pøevod do OV'
root - WARNING - yearOfApproval was not grabbed.
Traceback (most recent call last):
  File "C:\Osobni\rApp\rApp\acts.py", line 189, in extractData
    dict_offerDetailsAttr[key] = dict_detailsTableOfOffer[value]
KeyError: 'Rok kolaudace'
root - WARNING - s_gas was not grabbed.
Traceback (most recent call last):
  File "C:\Osobni\rApp\rApp\acts.py", line 207, in extractData
    s_gas = dict_detailsTableOfOffer['Plyn'][0]["value"]
KeyError: 'Plyn'
