2021-02-12 23:02:42,493 - root - WARNING - terraceSqMeter was not grabbed.
Traceback (most recent call last):
  File "C:\Osobni\rApp\rApp\extractDataFromOfferFlow.py", line 122, in execute
    dict_offerDetailsAttr[key] = dict_detailsTableOfOffer[value]
KeyError: 'Terasa'
2021-02-12 23:02:42,495 - root - WARNING - terrace was not grabbed.
Traceback (most recent call last):
  File "C:\Osobni\rApp\rApp\extractDataFromOfferFlow.py", line 122, in execute
    dict_offerDetailsAttr[key] = dict_detailsTableOfOffer[value]
KeyError: 'Terasa'
2021-02-12 23:02:42,495 - root - WARNING - idOrder was not grabbed.
Traceback (most recent call last):
  File "C:\Osobni\rApp\rApp\extractDataFromOfferFlow.py", line 122, in execute
    dict_offerDetailsAttr[key] = dict_detailsTableOfOffer[value]
KeyError: 'ID'
2021-02-12 23:02:42,496 - root - WARNING - barrieFree was not grabbed.
Traceback (most recent call last):
  File "C:\Osobni\rApp\rApp\extractDataFromOfferFlow.py", line 122, in execute
    dict_offerDetailsAttr[key] = dict_detailsTableOfOffer[value]
KeyError: 'Bezbariérový'
2021-02-12 23:02:42,496 - root - WARNING - parking was not grabbed.
Traceback (most recent call last):
  File "C:\Osobni\rApp\rApp\extractDataFromOfferFlow.py", line 122, in execute
    dict_offerDetailsAttr[key] = dict_detailsTableOfOffer[value]
KeyError: 'Parkování'
2021-02-12 23:02:42,497 - root - WARNING - garage was not grabbed.
Traceback (most recent call last):
  File "C:\Osobni\rApp\rApp\extractDataFromOfferFlow.py", line 122, in execute
    dict_offerDetailsAttr[key] = dict_detailsTableOfOffer[value]
KeyError: 'Garáž'
2021-02-12 23:02:42,497 - root - WARNING - transferToPersonalOwnership was not grabbed.
Traceback (most recent call last):
  File "C:\Osobni\rApp\rApp\extractDataFromOfferFlow.py", line 122, in execute
    dict_offerDetailsAttr[key] = dict_detailsTableOfOffer[value]
KeyError: 'Pøevod do OV'
2021-02-12 23:02:42,497 - root - WARNING - yearOfApproval was not grabbed.
Traceback (most recent call last):
  File "C:\Osobni\rApp\rApp\extractDataFromOfferFlow.py", line 122, in execute
    dict_offerDetailsAttr[key] = dict_detailsTableOfOffer[value]
KeyError: 'Rok kolaudace'
2021-02-12 23:02:42,497 - root - WARNING - gas was not grabbed.
Traceback (most recent call last):
  File "C:\Osobni\rApp\rApp\extractDataFromOfferFlow.py", line 139, in execute
    dict_offerDetailsAttr[key] = dict_detailsTableOfOffer[value][0]["value"]
KeyError: 'Plyn'
2021-02-12 23:02:42,498 - root - WARNING - roads was not grabbed.
Traceback (most recent call last):
  File "C:\Osobni\rApp\rApp\extractDataFromOfferFlow.py", line 139, in execute
    dict_offerDetailsAttr[key] = dict_detailsTableOfOffer[value][0]["value"]
KeyError: 'Komunikace'
2021-02-12 23:02:42,498 - root - WARNING - culturalHeritageDistance was not grabbed.
Traceback (most recent call last):
  File "C:\Osobni\rApp\rApp\extractDataFromOfferFlow.py", line 179, in execute
    dict_offerDetailsAttr[key] = dict_poi[value]
KeyError: 'Kulturní památka'
2021-02-12 23:02:42,498 - root - WARNING - tramDistance was not grabbed.
Traceback (most recent call last):
  File "C:\Osobni\rApp\rApp\extractDataFromOfferFlow.py", line 179, in execute
    dict_offerDetailsAttr[key] = dict_poi[value]
KeyError: 'Tram'
2021-02-12 23:02:42,499 - root - WARNING - metroDistance was not grabbed.
Traceback (most recent call last):
  File "C:\Osobni\rApp\rApp\extractDataFromOfferFlow.py", line 179, in execute
    dict_offerDetailsAttr[key] = dict_poi[value]
KeyError: 'Metro'
2021-02-12 23:02:42,499 - root - WARNING - naturalAttractionDistance was not grabbed.
Traceback (most recent call last):
  File "C:\Osobni\rApp\rApp\extractDataFromOfferFlow.py", line 179, in execute
    dict_offerDetailsAttr[key] = dict_poi[value]
KeyError: 'Pøírodní zajímavost'
2021-02-12 23:02:42,672 - googleapiclient.discovery_cache - WARNING - file_cache is unavailable when using oauth2client >= 4.0.0 or google-auth
Traceback (most recent call last):
  File "C:\Users\pavel\AppData\Local\Programs\Python\Python37-32\lib\site-packages\googleapiclient\discovery_cache\file_cache.py", line 33, in <module>
    from oauth2client.contrib.locked_file import LockedFile
ModuleNotFoundError: No module named 'oauth2client.contrib.locked_file'

During handling of the above exception, another exception occurred:

Traceback (most recent call last):
  File "C:\Users\pavel\AppData\Local\Programs\Python\Python37-32\lib\site-packages\googleapiclient\discovery_cache\file_cache.py", line 37, in <module>
    from oauth2client.locked_file import LockedFile
ModuleNotFoundError: No module named 'oauth2client.locked_file'

During handling of the above exception, another exception occurred:

Traceback (most recent call last):
  File "C:\Users\pavel\AppData\Local\Programs\Python\Python37-32\lib\site-packages\googleapiclient\discovery_cache\__init__.py", line 44, in autodetect
    from . import file_cache
  File "C:\Users\pavel\AppData\Local\Programs\Python\Python37-32\lib\site-packages\googleapiclient\discovery_cache\file_cache.py", line 41, in <module>
    "file_cache is unavailable when using oauth2client >= 4.0.0 or google-auth"
ImportError: file_cache is unavailable when using oauth2client >= 4.0.0 or google-auth
2021-02-12 23:02:43,548 - root - WARNING - terraceSqMeter was not grabbed.
Traceback (most recent call last):
  File "C:\Osobni\rApp\rApp\extractDataFromOfferFlow.py", line 122, in execute
    dict_offerDetailsAttr[key] = dict_detailsTableOfOffer[value]
KeyError: 'Terasa'
2021-02-12 23:02:43,548 - root - WARNING - terrace was not grabbed.
Traceback (most recent call last):
  File "C:\Osobni\rApp\rApp\extractDataFromOfferFlow.py", line 122, in execute
    dict_offerDetailsAttr[key] = dict_detailsTableOfOffer[value]
KeyError: 'Terasa'
2021-02-12 23:02:43,548 - root - WARNING - priceNote was not grabbed.
Traceback (most recent call last):
  File "C:\Osobni\rApp\rApp\extractDataFromOfferFlow.py", line 122, in execute
    dict_offerDetailsAttr[key] = dict_detailsTableOfOffer[value]
KeyError: 'Poznámka k cenì'
2021-02-12 23:02:43,551 - root - WARNING - location was not grabbed.
Traceback (most recent call last):
  File "C:\Osobni\rApp\rApp\extractDataFromOfferFlow.py", line 122, in execute
    dict_offerDetailsAttr[key] = dict_detailsTableOfOffer[value]
KeyError: 'Umístìní objektu'
2021-02-12 23:02:43,551 - root - WARNING - lift was not grabbed.
Traceback (most recent call last):
  File "C:\Osobni\rApp\rApp\extractDataFromOfferFlow.py", line 122, in execute
    dict_offerDetailsAttr[key] = dict_detailsTableOfOffer[value]
KeyError: 'Výtah'
2021-02-12 23:02:43,551 - root - WARNING - id was not grabbed.
Traceback (most recent call last):
  File "C:\Osobni\rApp\rApp\extractDataFromOfferFlow.py", line 122, in execute
    dict_offerDetailsAttr[key] = dict_detailsTableOfOffer[value]
KeyError: 'ID zakázky'
2021-02-12 23:02:43,552 - root - WARNING - energyPerformanceOfBuilding was not grabbed.
Traceback (most recent call last):
  File "C:\Osobni\rApp\rApp\extractDataFromOfferFlow.py", line 122, in execute
    dict_offerDetailsAttr[key] = dict_detailsTableOfOffer[value]
KeyError: 'Energetická nároènost budovy'
2021-02-12 23:02:43,552 - root - WARNING - barrieFree was not grabbed.
Traceback (most recent call last):
  File "C:\Osobni\rApp\rApp\extractDataFromOfferFlow.py", line 122, in execute
    dict_offerDetailsAttr[key] = dict_detailsTableOfOffer[value]
KeyError: 'Bezbariérový'
2021-02-12 23:02:43,552 - root - WARNING - parking was not grabbed.
Traceback (most recent call last):
  File "C:\Osobni\rApp\rApp\extractDataFromOfferFlow.py", line 122, in execute
    dict_offerDetailsAttr[key] = dict_detailsTableOfOffer[value]
KeyError: 'Parkování'
2021-02-12 23:02:43,553 - root - WARNING - garage was not grabbed.
Traceback (most recent call last):
  File "C:\Osobni\rApp\rApp\extractDataFromOfferFlow.py", line 122, in execute
    dict_offerDetailsAttr[key] = dict_detailsTableOfOffer[value]
KeyError: 'Garáž'
2021-02-12 23:02:43,553 - root - WARNING - equipped was not grabbed.
Traceback (most recent call last):
  File "C:\Osobni\rApp\rApp\extractDataFromOfferFlow.py", line 122, in execute
    dict_offerDetailsAttr[key] = dict_detailsTableOfOffer[value]
KeyError: 'Vybavení'
2021-02-12 23:02:43,553 - root - WARNING - transferToPersonalOwnership was not grabbed.
Traceback (most recent call last):
  File "C:\Osobni\rApp\rApp\extractDataFromOfferFlow.py", line 122, in execute
    dict_offerDetailsAttr[key] = dict_detailsTableOfOffer[value]
KeyError: 'Pøevod do OV'
2021-02-12 23:02:43,553 - root - WARNING - yearOfApproval was not grabbed.
Traceback (most recent call last):
  File "C:\Osobni\rApp\rApp\extractDataFromOfferFlow.py", line 122, in execute
    dict_offerDetailsAttr[key] = dict_detailsTableOfOffer[value]
KeyError: 'Rok kolaudace'
2021-02-12 23:02:43,553 - root - WARNING - transport was not grabbed.
Traceback (most recent call last):
  File "C:\Osobni\rApp\rApp\extractDataFromOfferFlow.py", line 139, in execute
    dict_offerDetailsAttr[key] = dict_detailsTableOfOffer[value][0]["value"]
KeyError: 'Doprava'
2021-02-12 23:02:43,553 - root - WARNING - water was not grabbed.
Traceback (most recent call last):
  File "C:\Osobni\rApp\rApp\extractDataFromOfferFlow.py", line 139, in execute
    dict_offerDetailsAttr[key] = dict_detailsTableOfOffer[value][0]["value"]
KeyError: 'Voda'
2021-02-12 23:02:43,553 - root - WARNING - gas was not grabbed.
Traceback (most recent call last):
  File "C:\Osobni\rApp\rApp\extractDataFromOfferFlow.py", line 139, in execute
    dict_offerDetailsAttr[key] = dict_detailsTableOfOffer[value][0]["value"]
KeyError: 'Plyn'
2021-02-12 23:02:43,553 - root - WARNING - heating was not grabbed.
Traceback (most recent call last):
  File "C:\Osobni\rApp\rApp\extractDataFromOfferFlow.py", line 139, in execute
    dict_offerDetailsAttr[key] = dict_detailsTableOfOffer[value][0]["value"]
KeyError: 'Topení'
2021-02-12 23:02:43,553 - root - WARNING - waste was not grabbed.
Traceback (most recent call last):
  File "C:\Osobni\rApp\rApp\extractDataFromOfferFlow.py", line 139, in execute
    dict_offerDetailsAttr[key] = dict_detailsTableOfOffer[value][0]["value"]
KeyError: 'Odpad'
2021-02-12 23:02:43,553 - root - WARNING - electricity was not grabbed.
Traceback (most recent call last):
  File "C:\Osobni\rApp\rApp\extractDataFromOfferFlow.py", line 139, in execute
    dict_offerDetailsAttr[key] = dict_detailsTableOfOffer[value][0]["value"]
KeyError: 'Elektøina'
2021-02-12 23:02:43,553 - root - WARNING - roads was not grabbed.
Traceback (most recent call last):
  File "C:\Osobni\rApp\rApp\extractDataFromOfferFlow.py", line 139, in execute
    dict_offerDetailsAttr[key] = dict_detailsTableOfOffer[value][0]["value"]
KeyError: 'Komunikace'
2021-02-12 23:02:43,553 - root - WARNING - culturalHeritageDistance was not grabbed.
Traceback (most recent call last):
  File "C:\Osobni\rApp\rApp\extractDataFromOfferFlow.py", line 179, in execute
    dict_offerDetailsAttr[key] = dict_poi[value]
KeyError: 'Kulturní památka'
2021-02-12 23:02:43,553 - root - WARNING - tramDistance was not grabbed.
Traceback (most recent call last):
  File "C:\Osobni\rApp\rApp\extractDataFromOfferFlow.py", line 179, in execute
    dict_offerDetailsAttr[key] = dict_poi[value]
KeyError: 'Tram'
2021-02-12 23:02:43,553 - root - WARNING - metroDistance was not grabbed.
Traceback (most recent call last):
  File "C:\Osobni\rApp\rApp\extractDataFromOfferFlow.py", line 179, in execute
    dict_offerDetailsAttr[key] = dict_poi[value]
KeyError: 'Metro'
2021-02-12 23:02:43,558 - root - WARNING - naturalAttractionDistance was not grabbed.
Traceback (most recent call last):
  File "C:\Osobni\rApp\rApp\extractDataFromOfferFlow.py", line 179, in execute
    dict_offerDetailsAttr[key] = dict_poi[value]
KeyError: 'Pøírodní zajímavost'
2021-02-12 23:02:43,574 - googleapiclient.discovery_cache - WARNING - file_cache is unavailable when using oauth2client >= 4.0.0 or google-auth
Traceback (most recent call last):
  File "C:\Users\pavel\AppData\Local\Programs\Python\Python37-32\lib\site-packages\googleapiclient\discovery_cache\file_cache.py", line 33, in <module>
    from oauth2client.contrib.locked_file import LockedFile
ModuleNotFoundError: No module named 'oauth2client.contrib.locked_file'

During handling of the above exception, another exception occurred:

Traceback (most recent call last):
  File "C:\Users\pavel\AppData\Local\Programs\Python\Python37-32\lib\site-packages\googleapiclient\discovery_cache\file_cache.py", line 37, in <module>
    from oauth2client.locked_file import LockedFile
ModuleNotFoundError: No module named 'oauth2client.locked_file'

During handling of the above exception, another exception occurred:

Traceback (most recent call last):
  File "C:\Users\pavel\AppData\Local\Programs\Python\Python37-32\lib\site-packages\googleapiclient\discovery_cache\__init__.py", line 44, in autodetect
    from . import file_cache
  File "C:\Users\pavel\AppData\Local\Programs\Python\Python37-32\lib\site-packages\googleapiclient\discovery_cache\file_cache.py", line 41, in <module>
    "file_cache is unavailable when using oauth2client >= 4.0.0 or google-auth"
ImportError: file_cache is unavailable when using oauth2client >= 4.0.0 or google-auth
2021-02-12 23:02:44,881 - root - WARNING - terraceSqMeter was not grabbed.
Traceback (most recent call last):
  File "C:\Osobni\rApp\rApp\extractDataFromOfferFlow.py", line 122, in execute
    dict_offerDetailsAttr[key] = dict_detailsTableOfOffer[value]
KeyError: 'Terasa'
2021-02-12 23:02:44,882 - root - WARNING - terrace was not grabbed.
Traceback (most recent call last):
  File "C:\Osobni\rApp\rApp\extractDataFromOfferFlow.py", line 122, in execute
    dict_offerDetailsAttr[key] = dict_detailsTableOfOffer[value]
KeyError: 'Terasa'
2021-02-12 23:02:44,882 - root - WARNING - idOrder was not grabbed.
Traceback (most recent call last):
  File "C:\Osobni\rApp\rApp\extractDataFromOfferFlow.py", line 122, in execute
    dict_offerDetailsAttr[key] = dict_detailsTableOfOffer[value]
KeyError: 'ID'
2021-02-12 23:02:44,883 - root - WARNING - barrieFree was not grabbed.
Traceback (most recent call last):
  File "C:\Osobni\rApp\rApp\extractDataFromOfferFlow.py", line 122, in execute
    dict_offerDetailsAttr[key] = dict_detailsTableOfOffer[value]
KeyError: 'Bezbariérový'
2021-02-12 23:02:44,883 - root - WARNING - parking was not grabbed.
Traceback (most recent call last):
  File "C:\Osobni\rApp\rApp\extractDataFromOfferFlow.py", line 122, in execute
    dict_offerDetailsAttr[key] = dict_detailsTableOfOffer[value]
KeyError: 'Parkování'
2021-02-12 23:02:44,883 - root - WARNING - garage was not grabbed.
Traceback (most recent call last):
  File "C:\Osobni\rApp\rApp\extractDataFromOfferFlow.py", line 122, in execute
    dict_offerDetailsAttr[key] = dict_detailsTableOfOffer[value]
KeyError: 'Garáž'
2021-02-12 23:02:44,883 - root - WARNING - transferToPersonalOwnership was not grabbed.
Traceback (most recent call last):
  File "C:\Osobni\rApp\rApp\extractDataFromOfferFlow.py", line 122, in execute
    dict_offerDetailsAttr[key] = dict_detailsTableOfOffer[value]
KeyError: 'Pøevod do OV'
2021-02-12 23:02:44,883 - root - WARNING - yearOfApproval was not grabbed.
Traceback (most recent call last):
  File "C:\Osobni\rApp\rApp\extractDataFromOfferFlow.py", line 122, in execute
    dict_offerDetailsAttr[key] = dict_detailsTableOfOffer[value]
KeyError: 'Rok kolaudace'
2021-02-12 23:02:44,883 - root - WARNING - gas was not grabbed.
Traceback (most recent call last):
  File "C:\Osobni\rApp\rApp\extractDataFromOfferFlow.py", line 139, in execute
    dict_offerDetailsAttr[key] = dict_detailsTableOfOffer[value][0]["value"]
KeyError: 'Plyn'
2021-02-12 23:02:44,883 - root - WARNING - roads was not grabbed.
Traceback (most recent call last):
  File "C:\Osobni\rApp\rApp\extractDataFromOfferFlow.py", line 139, in execute
    dict_offerDetailsAttr[key] = dict_detailsTableOfOffer[value][0]["value"]
KeyError: 'Komunikace'
2021-02-12 23:02:44,883 - root - WARNING - culturalHeritageDistance was not grabbed.
Traceback (most recent call last):
  File "C:\Osobni\rApp\rApp\extractDataFromOfferFlow.py", line 179, in execute
    dict_offerDetailsAttr[key] = dict_poi[value]
KeyError: 'Kulturní památka'
2021-02-12 23:02:44,883 - root - WARNING - tramDistance was not grabbed.
Traceback (most recent call last):
  File "C:\Osobni\rApp\rApp\extractDataFromOfferFlow.py", line 179, in execute
    dict_offerDetailsAttr[key] = dict_poi[value]
KeyError: 'Tram'
2021-02-12 23:02:44,883 - root - WARNING - metroDistance was not grabbed.
Traceback (most recent call last):
  File "C:\Osobni\rApp\rApp\extractDataFromOfferFlow.py", line 179, in execute
    dict_offerDetailsAttr[key] = dict_poi[value]
KeyError: 'Metro'
2021-02-12 23:02:44,883 - root - WARNING - cinemaDistance was not grabbed.
Traceback (most recent call last):
  File "C:\Osobni\rApp\rApp\extractDataFromOfferFlow.py", line 179, in execute
    dict_offerDetailsAttr[key] = dict_poi[value]
KeyError: 'Kino'
2021-02-12 23:02:44,883 - root - WARNING - theaterDistance was not grabbed.
Traceback (most recent call last):
  File "C:\Osobni\rApp\rApp\extractDataFromOfferFlow.py", line 179, in execute
    dict_offerDetailsAttr[key] = dict_poi[value]
KeyError: 'Divadlo'
2021-02-12 23:02:44,883 - root - WARNING - storeDistance was not grabbed.
Traceback (most recent call last):
  File "C:\Osobni\rApp\rApp\extractDataFromOfferFlow.py", line 179, in execute
    dict_offerDetailsAttr[key] = dict_poi[value]
KeyError: 'Obchod'
2021-02-12 23:02:44,883 - root - WARNING - naturalAttractionDistance was not grabbed.
Traceback (most recent call last):
  File "C:\Osobni\rApp\rApp\extractDataFromOfferFlow.py", line 179, in execute
    dict_offerDetailsAttr[key] = dict_poi[value]
KeyError: 'Pøírodní zajímavost'
2021-02-12 23:02:44,891 - googleapiclient.discovery_cache - WARNING - file_cache is unavailable when using oauth2client >= 4.0.0 or google-auth
Traceback (most recent call last):
  File "C:\Users\pavel\AppData\Local\Programs\Python\Python37-32\lib\site-packages\googleapiclient\discovery_cache\file_cache.py", line 33, in <module>
    from oauth2client.contrib.locked_file import LockedFile
ModuleNotFoundError: No module named 'oauth2client.contrib.locked_file'

During handling of the above exception, another exception occurred:

Traceback (most recent call last):
  File "C:\Users\pavel\AppData\Local\Programs\Python\Python37-32\lib\site-packages\googleapiclient\discovery_cache\file_cache.py", line 37, in <module>
    from oauth2client.locked_file import LockedFile
ModuleNotFoundError: No module named 'oauth2client.locked_file'

During handling of the above exception, another exception occurred:

Traceback (most recent call last):
  File "C:\Users\pavel\AppData\Local\Programs\Python\Python37-32\lib\site-packages\googleapiclient\discovery_cache\__init__.py", line 44, in autodetect
    from . import file_cache
  File "C:\Users\pavel\AppData\Local\Programs\Python\Python37-32\lib\site-packages\googleapiclient\discovery_cache\file_cache.py", line 41, in <module>
    "file_cache is unavailable when using oauth2client >= 4.0.0 or google-auth"
ImportError: file_cache is unavailable when using oauth2client >= 4.0.0 or google-auth
2021-02-12 23:02:45,899 - root - WARNING - terraceSqMeter was not grabbed.
Traceback (most recent call last):
  File "C:\Osobni\rApp\rApp\extractDataFromOfferFlow.py", line 122, in execute
    dict_offerDetailsAttr[key] = dict_detailsTableOfOffer[value]
KeyError: 'Terasa'
2021-02-12 23:02:45,900 - root - WARNING - terrace was not grabbed.
Traceback (most recent call last):
  File "C:\Osobni\rApp\rApp\extractDataFromOfferFlow.py", line 122, in execute
    dict_offerDetailsAttr[key] = dict_detailsTableOfOffer[value]
KeyError: 'Terasa'
2021-02-12 23:02:45,900 - root - WARNING - priceNote was not grabbed.
Traceback (most recent call last):
  File "C:\Osobni\rApp\rApp\extractDataFromOfferFlow.py", line 122, in execute
    dict_offerDetailsAttr[key] = dict_detailsTableOfOffer[value]
KeyError: 'Poznámka k cenì'
2021-02-12 23:02:45,900 - root - WARNING - idOrder was not grabbed.
Traceback (most recent call last):
  File "C:\Osobni\rApp\rApp\extractDataFromOfferFlow.py", line 122, in execute
    dict_offerDetailsAttr[key] = dict_detailsTableOfOffer[value]
KeyError: 'ID'
2021-02-12 23:02:45,900 - root - WARNING - parking was not grabbed.
Traceback (most recent call last):
  File "C:\Osobni\rApp\rApp\extractDataFromOfferFlow.py", line 122, in execute
    dict_offerDetailsAttr[key] = dict_detailsTableOfOffer[value]
KeyError: 'Parkování'
2021-02-12 23:02:45,901 - root - WARNING - garage was not grabbed.
Traceback (most recent call last):
  File "C:\Osobni\rApp\rApp\extractDataFromOfferFlow.py", line 122, in execute
    dict_offerDetailsAttr[key] = dict_detailsTableOfOffer[value]
KeyError: 'Garáž'
2021-02-12 23:02:45,901 - root - WARNING - equipped was not grabbed.
Traceback (most recent call last):
  File "C:\Osobni\rApp\rApp\extractDataFromOfferFlow.py", line 122, in execute
    dict_offerDetailsAttr[key] = dict_detailsTableOfOffer[value]
KeyError: 'Vybavení'
2021-02-12 23:02:45,901 - root - WARNING - transferToPersonalOwnership was not grabbed.
Traceback (most recent call last):
  File "C:\Osobni\rApp\rApp\extractDataFromOfferFlow.py", line 122, in execute
    dict_offerDetailsAttr[key] = dict_detailsTableOfOffer[value]
KeyError: 'Pøevod do OV'
2021-02-12 23:02:45,901 - root - WARNING - yearOfApproval was not grabbed.
Traceback (most recent call last):
  File "C:\Osobni\rApp\rApp\extractDataFromOfferFlow.py", line 122, in execute
    dict_offerDetailsAttr[key] = dict_detailsTableOfOffer[value]
KeyError: 'Rok kolaudace'
2021-02-12 23:02:45,902 - root - WARNING - gas was not grabbed.
Traceback (most recent call last):
  File "C:\Osobni\rApp\rApp\extractDataFromOfferFlow.py", line 139, in execute
    dict_offerDetailsAttr[key] = dict_detailsTableOfOffer[value][0]["value"]
KeyError: 'Plyn'
2021-02-12 23:02:45,902 - root - WARNING - culturalHeritageDistance was not grabbed.
Traceback (most recent call last):
  File "C:\Osobni\rApp\rApp\extractDataFromOfferFlow.py", line 179, in execute
    dict_offerDetailsAttr[key] = dict_poi[value]
KeyError: 'Kulturní památka'
2021-02-12 23:02:45,902 - root - WARNING - tramDistance was not grabbed.
Traceback (most recent call last):
  File "C:\Osobni\rApp\rApp\extractDataFromOfferFlow.py", line 179, in execute
    dict_offerDetailsAttr[key] = dict_poi[value]
KeyError: 'Tram'
2021-02-12 23:02:45,902 - root - WARNING - metroDistance was not grabbed.
Traceback (most recent call last):
  File "C:\Osobni\rApp\rApp\extractDataFromOfferFlow.py", line 179, in execute
    dict_offerDetailsAttr[key] = dict_poi[value]
KeyError: 'Metro'
2021-02-12 23:02:45,902 - root - WARNING - naturalAttractionDistance was not grabbed.
Traceback (most recent call last):
  File "C:\Osobni\rApp\rApp\extractDataFromOfferFlow.py", line 179, in execute
    dict_offerDetailsAttr[key] = dict_poi[value]
KeyError: 'Pøírodní zajímavost'
2021-02-12 23:02:45,902 - googleapiclient.discovery_cache - WARNING - file_cache is unavailable when using oauth2client >= 4.0.0 or google-auth
Traceback (most recent call last):
  File "C:\Users\pavel\AppData\Local\Programs\Python\Python37-32\lib\site-packages\googleapiclient\discovery_cache\file_cache.py", line 33, in <module>
    from oauth2client.contrib.locked_file import LockedFile
ModuleNotFoundError: No module named 'oauth2client.contrib.locked_file'

During handling of the above exception, another exception occurred:

Traceback (most recent call last):
  File "C:\Users\pavel\AppData\Local\Programs\Python\Python37-32\lib\site-packages\googleapiclient\discovery_cache\file_cache.py", line 37, in <module>
    from oauth2client.locked_file import LockedFile
ModuleNotFoundError: No module named 'oauth2client.locked_file'

During handling of the above exception, another exception occurred:

Traceback (most recent call last):
  File "C:\Users\pavel\AppData\Local\Programs\Python\Python37-32\lib\site-packages\googleapiclient\discovery_cache\__init__.py", line 44, in autodetect
    from . import file_cache
  File "C:\Users\pavel\AppData\Local\Programs\Python\Python37-32\lib\site-packages\googleapiclient\discovery_cache\file_cache.py", line 41, in <module>
    "file_cache is unavailable when using oauth2client >= 4.0.0 or google-auth"
ImportError: file_cache is unavailable when using oauth2client >= 4.0.0 or google-auth
2021-02-12 23:02:46,971 - root - WARNING - priceNote was not grabbed.
Traceback (most recent call last):
  File "C:\Osobni\rApp\rApp\extractDataFromOfferFlow.py", line 122, in execute
    dict_offerDetailsAttr[key] = dict_detailsTableOfOffer[value]
KeyError: 'Poznámka k cenì'
2021-02-12 23:02:46,971 - root - WARNING - location was not grabbed.
Traceback (most recent call last):
  File "C:\Osobni\rApp\rApp\extractDataFromOfferFlow.py", line 122, in execute
    dict_offerDetailsAttr[key] = dict_detailsTableOfOffer[value]
KeyError: 'Umístìní objektu'
2021-02-12 23:02:46,971 - root - WARNING - idOrder was not grabbed.
Traceback (most recent call last):
  File "C:\Osobni\rApp\rApp\extractDataFromOfferFlow.py", line 122, in execute
    dict_offerDetailsAttr[key] = dict_detailsTableOfOffer[value]
KeyError: 'ID'
2021-02-12 23:02:46,972 - root - WARNING - parking was not grabbed.
Traceback (most recent call last):
  File "C:\Osobni\rApp\rApp\extractDataFromOfferFlow.py", line 122, in execute
    dict_offerDetailsAttr[key] = dict_detailsTableOfOffer[value]
KeyError: 'Parkování'
2021-02-12 23:02:46,972 - root - WARNING - garage was not grabbed.
Traceback (most recent call last):
  File "C:\Osobni\rApp\rApp\extractDataFromOfferFlow.py", line 122, in execute
    dict_offerDetailsAttr[key] = dict_detailsTableOfOffer[value]
KeyError: 'Garáž'
2021-02-12 23:02:46,972 - root - WARNING - transferToPersonalOwnership was not grabbed.
Traceback (most recent call last):
  File "C:\Osobni\rApp\rApp\extractDataFromOfferFlow.py", line 122, in execute
    dict_offerDetailsAttr[key] = dict_detailsTableOfOffer[value]
KeyError: 'Pøevod do OV'
2021-02-12 23:02:46,973 - root - WARNING - gas was not grabbed.
Traceback (most recent call last):
  File "C:\Osobni\rApp\rApp\extractDataFromOfferFlow.py", line 139, in execute
    dict_offerDetailsAttr[key] = dict_detailsTableOfOffer[value][0]["value"]
KeyError: 'Plyn'
2021-02-12 23:02:46,973 - root - WARNING - electricity was not grabbed.
Traceback (most recent call last):
  File "C:\Osobni\rApp\rApp\extractDataFromOfferFlow.py", line 139, in execute
    dict_offerDetailsAttr[key] = dict_detailsTableOfOffer[value][0]["value"]
KeyError: 'Elektøina'
2021-02-12 23:02:46,973 - root - WARNING - culturalHeritageDistance was not grabbed.
Traceback (most recent call last):
  File "C:\Osobni\rApp\rApp\extractDataFromOfferFlow.py", line 179, in execute
    dict_offerDetailsAttr[key] = dict_poi[value]
KeyError: 'Kulturní památka'
2021-02-12 23:02:46,973 - root - WARNING - tramDistance was not grabbed.
Traceback (most recent call last):
  File "C:\Osobni\rApp\rApp\extractDataFromOfferFlow.py", line 179, in execute
    dict_offerDetailsAttr[key] = dict_poi[value]
KeyError: 'Tram'
2021-02-12 23:02:46,973 - root - WARNING - metroDistance was not grabbed.
Traceback (most recent call last):
  File "C:\Osobni\rApp\rApp\extractDataFromOfferFlow.py", line 179, in execute
    dict_offerDetailsAttr[key] = dict_poi[value]
KeyError: 'Metro'
2021-02-12 23:02:46,973 - root - WARNING - naturalAttractionDistance was not grabbed.
Traceback (most recent call last):
  File "C:\Osobni\rApp\rApp\extractDataFromOfferFlow.py", line 179, in execute
    dict_offerDetailsAttr[key] = dict_poi[value]
KeyError: 'Pøírodní zajímavost'
2021-02-12 23:02:46,978 - googleapiclient.discovery_cache - WARNING - file_cache is unavailable when using oauth2client >= 4.0.0 or google-auth
Traceback (most recent call last):
  File "C:\Users\pavel\AppData\Local\Programs\Python\Python37-32\lib\site-packages\googleapiclient\discovery_cache\file_cache.py", line 33, in <module>
    from oauth2client.contrib.locked_file import LockedFile
ModuleNotFoundError: No module named 'oauth2client.contrib.locked_file'

During handling of the above exception, another exception occurred:

Traceback (most recent call last):
  File "C:\Users\pavel\AppData\Local\Programs\Python\Python37-32\lib\site-packages\googleapiclient\discovery_cache\file_cache.py", line 37, in <module>
    from oauth2client.locked_file import LockedFile
ModuleNotFoundError: No module named 'oauth2client.locked_file'

During handling of the above exception, another exception occurred:

Traceback (most recent call last):
  File "C:\Users\pavel\AppData\Local\Programs\Python\Python37-32\lib\site-packages\googleapiclient\discovery_cache\__init__.py", line 44, in autodetect
    from . import file_cache
  File "C:\Users\pavel\AppData\Local\Programs\Python\Python37-32\lib\site-packages\googleapiclient\discovery_cache\file_cache.py", line 41, in <module>
    "file_cache is unavailable when using oauth2client >= 4.0.0 or google-auth"
ImportError: file_cache is unavailable when using oauth2client >= 4.0.0 or google-auth
2021-02-12 23:02:48,133 - root - WARNING - terraceSqMeter was not grabbed.
Traceback (most recent call last):
  File "C:\Osobni\rApp\rApp\extractDataFromOfferFlow.py", line 122, in execute
    dict_offerDetailsAttr[key] = dict_detailsTableOfOffer[value]
KeyError: 'Terasa'
2021-02-12 23:02:48,133 - root - WARNING - terrace was not grabbed.
Traceback (most recent call last):
  File "C:\Osobni\rApp\rApp\extractDataFromOfferFlow.py", line 122, in execute
    dict_offerDetailsAttr[key] = dict_detailsTableOfOffer[value]
KeyError: 'Terasa'
2021-02-12 23:02:48,133 - root - WARNING - priceNote was not grabbed.
Traceback (most recent call last):
  File "C:\Osobni\rApp\rApp\extractDataFromOfferFlow.py", line 122, in execute
    dict_offerDetailsAttr[key] = dict_detailsTableOfOffer[value]
KeyError: 'Poznámka k cenì'
2021-02-12 23:02:48,133 - root - WARNING - idOrder was not grabbed.
Traceback (most recent call last):
  File "C:\Osobni\rApp\rApp\extractDataFromOfferFlow.py", line 122, in execute
    dict_offerDetailsAttr[key] = dict_detailsTableOfOffer[value]
KeyError: 'ID'
2021-02-12 23:02:48,133 - root - WARNING - barrieFree was not grabbed.
Traceback (most recent call last):
  File "C:\Osobni\rApp\rApp\extractDataFromOfferFlow.py", line 122, in execute
    dict_offerDetailsAttr[key] = dict_detailsTableOfOffer[value]
KeyError: 'Bezbariérový'
2021-02-12 23:02:48,133 - root - WARNING - parking was not grabbed.
Traceback (most recent call last):
  File "C:\Osobni\rApp\rApp\extractDataFromOfferFlow.py", line 122, in execute
    dict_offerDetailsAttr[key] = dict_detailsTableOfOffer[value]
KeyError: 'Parkování'
2021-02-12 23:02:48,133 - root - WARNING - garage was not grabbed.
Traceback (most recent call last):
  File "C:\Osobni\rApp\rApp\extractDataFromOfferFlow.py", line 122, in execute
    dict_offerDetailsAttr[key] = dict_detailsTableOfOffer[value]
KeyError: 'Garáž'
2021-02-12 23:02:48,133 - root - WARNING - yearOfApproval was not grabbed.
Traceback (most recent call last):
  File "C:\Osobni\rApp\rApp\extractDataFromOfferFlow.py", line 122, in execute
    dict_offerDetailsAttr[key] = dict_detailsTableOfOffer[value]
KeyError: 'Rok kolaudace'
2021-02-12 23:02:48,133 - root - WARNING - culturalHeritageDistance was not grabbed.
Traceback (most recent call last):
  File "C:\Osobni\rApp\rApp\extractDataFromOfferFlow.py", line 179, in execute
    dict_offerDetailsAttr[key] = dict_poi[value]
KeyError: 'Kulturní památka'
2021-02-12 23:02:48,133 - root - WARNING - tramDistance was not grabbed.
Traceback (most recent call last):
  File "C:\Osobni\rApp\rApp\extractDataFromOfferFlow.py", line 179, in execute
    dict_offerDetailsAttr[key] = dict_poi[value]
KeyError: 'Tram'
2021-02-12 23:02:48,133 - root - WARNING - metroDistance was not grabbed.
Traceback (most recent call last):
  File "C:\Osobni\rApp\rApp\extractDataFromOfferFlow.py", line 179, in execute
    dict_offerDetailsAttr[key] = dict_poi[value]
KeyError: 'Metro'
2021-02-12 23:02:48,133 - root - WARNING - naturalAttractionDistance was not grabbed.
Traceback (most recent call last):
  File "C:\Osobni\rApp\rApp\extractDataFromOfferFlow.py", line 179, in execute
    dict_offerDetailsAttr[key] = dict_poi[value]
KeyError: 'Pøírodní zajímavost'
2021-02-12 23:02:48,142 - googleapiclient.discovery_cache - WARNING - file_cache is unavailable when using oauth2client >= 4.0.0 or google-auth
Traceback (most recent call last):
  File "C:\Users\pavel\AppData\Local\Programs\Python\Python37-32\lib\site-packages\googleapiclient\discovery_cache\file_cache.py", line 33, in <module>
    from oauth2client.contrib.locked_file import LockedFile
ModuleNotFoundError: No module named 'oauth2client.contrib.locked_file'

During handling of the above exception, another exception occurred:

Traceback (most recent call last):
  File "C:\Users\pavel\AppData\Local\Programs\Python\Python37-32\lib\site-packages\googleapiclient\discovery_cache\file_cache.py", line 37, in <module>
    from oauth2client.locked_file import LockedFile
ModuleNotFoundError: No module named 'oauth2client.locked_file'

During handling of the above exception, another exception occurred:

Traceback (most recent call last):
  File "C:\Users\pavel\AppData\Local\Programs\Python\Python37-32\lib\site-packages\googleapiclient\discovery_cache\__init__.py", line 44, in autodetect
    from . import file_cache
  File "C:\Users\pavel\AppData\Local\Programs\Python\Python37-32\lib\site-packages\googleapiclient\discovery_cache\file_cache.py", line 41, in <module>
    "file_cache is unavailable when using oauth2client >= 4.0.0 or google-auth"
ImportError: file_cache is unavailable when using oauth2client >= 4.0.0 or google-auth
2021-02-12 23:02:49,082 - root - WARNING - terraceSqMeter was not grabbed.
Traceback (most recent call last):
  File "C:\Osobni\rApp\rApp\extractDataFromOfferFlow.py", line 122, in execute
    dict_offerDetailsAttr[key] = dict_detailsTableOfOffer[value]
KeyError: 'Terasa'
2021-02-12 23:02:49,082 - root - WARNING - terrace was not grabbed.
Traceback (most recent call last):
  File "C:\Osobni\rApp\rApp\extractDataFromOfferFlow.py", line 122, in execute
    dict_offerDetailsAttr[key] = dict_detailsTableOfOffer[value]
KeyError: 'Terasa'
2021-02-12 23:02:49,082 - root - WARNING - cellarSqMeter was not grabbed.
Traceback (most recent call last):
  File "C:\Osobni\rApp\rApp\extractDataFromOfferFlow.py", line 122, in execute
    dict_offerDetailsAttr[key] = dict_detailsTableOfOffer[value]
KeyError: 'Sklep'
2021-02-12 23:02:49,082 - root - WARNING - cellar was not grabbed.
Traceback (most recent call last):
  File "C:\Osobni\rApp\rApp\extractDataFromOfferFlow.py", line 122, in execute
    dict_offerDetailsAttr[key] = dict_detailsTableOfOffer[value]
KeyError: 'Sklep'
2021-02-12 23:02:49,082 - root - WARNING - priceNote was not grabbed.
Traceback (most recent call last):
  File "C:\Osobni\rApp\rApp\extractDataFromOfferFlow.py", line 122, in execute
    dict_offerDetailsAttr[key] = dict_detailsTableOfOffer[value]
KeyError: 'Poznámka k cenì'
2021-02-12 23:02:49,082 - root - WARNING - idOrder was not grabbed.
Traceback (most recent call last):
  File "C:\Osobni\rApp\rApp\extractDataFromOfferFlow.py", line 122, in execute
    dict_offerDetailsAttr[key] = dict_detailsTableOfOffer[value]
KeyError: 'ID'
2021-02-12 23:02:49,082 - root - WARNING - barrieFree was not grabbed.
Traceback (most recent call last):
  File "C:\Osobni\rApp\rApp\extractDataFromOfferFlow.py", line 122, in execute
    dict_offerDetailsAttr[key] = dict_detailsTableOfOffer[value]
KeyError: 'Bezbariérový'
2021-02-12 23:02:49,082 - root - WARNING - parking was not grabbed.
Traceback (most recent call last):
  File "C:\Osobni\rApp\rApp\extractDataFromOfferFlow.py", line 122, in execute
    dict_offerDetailsAttr[key] = dict_detailsTableOfOffer[value]
KeyError: 'Parkování'
2021-02-12 23:02:49,082 - root - WARNING - garage was not grabbed.
Traceback (most recent call last):
  File "C:\Osobni\rApp\rApp\extractDataFromOfferFlow.py", line 122, in execute
    dict_offerDetailsAttr[key] = dict_detailsTableOfOffer[value]
KeyError: 'Garáž'
2021-02-12 23:02:49,082 - root - WARNING - transferToPersonalOwnership was not grabbed.
Traceback (most recent call last):
  File "C:\Osobni\rApp\rApp\extractDataFromOfferFlow.py", line 122, in execute
    dict_offerDetailsAttr[key] = dict_detailsTableOfOffer[value]
KeyError: 'Pøevod do OV'
2021-02-12 23:02:49,088 - root - WARNING - yearOfApproval was not grabbed.
Traceback (most recent call last):
  File "C:\Osobni\rApp\rApp\extractDataFromOfferFlow.py", line 122, in execute
    dict_offerDetailsAttr[key] = dict_detailsTableOfOffer[value]
KeyError: 'Rok kolaudace'
2021-02-12 23:02:49,088 - root - WARNING - transport was not grabbed.
Traceback (most recent call last):
  File "C:\Osobni\rApp\rApp\extractDataFromOfferFlow.py", line 139, in execute
    dict_offerDetailsAttr[key] = dict_detailsTableOfOffer[value][0]["value"]
KeyError: 'Doprava'
2021-02-12 23:02:49,088 - root - WARNING - water was not grabbed.
Traceback (most recent call last):
  File "C:\Osobni\rApp\rApp\extractDataFromOfferFlow.py", line 139, in execute
    dict_offerDetailsAttr[key] = dict_detailsTableOfOffer[value][0]["value"]
KeyError: 'Voda'
2021-02-12 23:02:49,088 - root - WARNING - gas was not grabbed.
Traceback (most recent call last):
  File "C:\Osobni\rApp\rApp\extractDataFromOfferFlow.py", line 139, in execute
    dict_offerDetailsAttr[key] = dict_detailsTableOfOffer[value][0]["value"]
KeyError: 'Plyn'
2021-02-12 23:02:49,088 - root - WARNING - electricity was not grabbed.
Traceback (most recent call last):
  File "C:\Osobni\rApp\rApp\extractDataFromOfferFlow.py", line 139, in execute
    dict_offerDetailsAttr[key] = dict_detailsTableOfOffer[value][0]["value"]
KeyError: 'Elektøina'
2021-02-12 23:02:49,088 - root - WARNING - culturalHeritageDistance was not grabbed.
Traceback (most recent call last):
  File "C:\Osobni\rApp\rApp\extractDataFromOfferFlow.py", line 179, in execute
    dict_offerDetailsAttr[key] = dict_poi[value]
KeyError: 'Kulturní památka'
2021-02-12 23:02:49,088 - root - WARNING - tramDistance was not grabbed.
Traceback (most recent call last):
  File "C:\Osobni\rApp\rApp\extractDataFromOfferFlow.py", line 179, in execute
    dict_offerDetailsAttr[key] = dict_poi[value]
KeyError: 'Tram'
2021-02-12 23:02:49,090 - root - WARNING - metroDistance was not grabbed.
Traceback (most recent call last):
  File "C:\Osobni\rApp\rApp\extractDataFromOfferFlow.py", line 179, in execute
    dict_offerDetailsAttr[key] = dict_poi[value]
KeyError: 'Metro'
2021-02-12 23:02:49,090 - root - WARNING - theaterDistance was not grabbed.
Traceback (most recent call last):
  File "C:\Osobni\rApp\rApp\extractDataFromOfferFlow.py", line 179, in execute
    dict_offerDetailsAttr[key] = dict_poi[value]
KeyError: 'Divadlo'
2021-02-12 23:02:49,090 - root - WARNING - naturalAttractionDistance was not grabbed.
Traceback (most recent call last):
  File "C:\Osobni\rApp\rApp\extractDataFromOfferFlow.py", line 179, in execute
    dict_offerDetailsAttr[key] = dict_poi[value]
KeyError: 'Pøírodní zajímavost'
2021-02-12 23:02:49,091 - googleapiclient.discovery_cache - WARNING - file_cache is unavailable when using oauth2client >= 4.0.0 or google-auth
Traceback (most recent call last):
  File "C:\Users\pavel\AppData\Local\Programs\Python\Python37-32\lib\site-packages\googleapiclient\discovery_cache\file_cache.py", line 33, in <module>
    from oauth2client.contrib.locked_file import LockedFile
ModuleNotFoundError: No module named 'oauth2client.contrib.locked_file'

During handling of the above exception, another exception occurred:

Traceback (most recent call last):
  File "C:\Users\pavel\AppData\Local\Programs\Python\Python37-32\lib\site-packages\googleapiclient\discovery_cache\file_cache.py", line 37, in <module>
    from oauth2client.locked_file import LockedFile
ModuleNotFoundError: No module named 'oauth2client.locked_file'

During handling of the above exception, another exception occurred:

Traceback (most recent call last):
  File "C:\Users\pavel\AppData\Local\Programs\Python\Python37-32\lib\site-packages\googleapiclient\discovery_cache\__init__.py", line 44, in autodetect
    from . import file_cache
  File "C:\Users\pavel\AppData\Local\Programs\Python\Python37-32\lib\site-packages\googleapiclient\discovery_cache\file_cache.py", line 41, in <module>
    "file_cache is unavailable when using oauth2client >= 4.0.0 or google-auth"
ImportError: file_cache is unavailable when using oauth2client >= 4.0.0 or google-auth
2021-02-12 23:02:50,152 - root - WARNING - terraceSqMeter was not grabbed.
Traceback (most recent call last):
  File "C:\Osobni\rApp\rApp\extractDataFromOfferFlow.py", line 122, in execute
    dict_offerDetailsAttr[key] = dict_detailsTableOfOffer[value]
KeyError: 'Terasa'
2021-02-12 23:02:50,152 - root - WARNING - terrace was not grabbed.
Traceback (most recent call last):
  File "C:\Osobni\rApp\rApp\extractDataFromOfferFlow.py", line 122, in execute
    dict_offerDetailsAttr[key] = dict_detailsTableOfOffer[value]
KeyError: 'Terasa'
2021-02-12 23:02:50,159 - root - WARNING - cellarSqMeter was not grabbed.
Traceback (most recent call last):
  File "C:\Osobni\rApp\rApp\extractDataFromOfferFlow.py", line 122, in execute
    dict_offerDetailsAttr[key] = dict_detailsTableOfOffer[value]
KeyError: 'Sklep'
2021-02-12 23:02:50,159 - root - WARNING - cellar was not grabbed.
Traceback (most recent call last):
  File "C:\Osobni\rApp\rApp\extractDataFromOfferFlow.py", line 122, in execute
    dict_offerDetailsAttr[key] = dict_detailsTableOfOffer[value]
KeyError: 'Sklep'
2021-02-12 23:02:50,160 - root - WARNING - idOrder was not grabbed.
Traceback (most recent call last):
  File "C:\Osobni\rApp\rApp\extractDataFromOfferFlow.py", line 122, in execute
    dict_offerDetailsAttr[key] = dict_detailsTableOfOffer[value]
KeyError: 'ID'
2021-02-12 23:02:50,160 - root - WARNING - barrieFree was not grabbed.
Traceback (most recent call last):
  File "C:\Osobni\rApp\rApp\extractDataFromOfferFlow.py", line 122, in execute
    dict_offerDetailsAttr[key] = dict_detailsTableOfOffer[value]
KeyError: 'Bezbariérový'
2021-02-12 23:02:50,161 - root - WARNING - parking was not grabbed.
Traceback (most recent call last):
  File "C:\Osobni\rApp\rApp\extractDataFromOfferFlow.py", line 122, in execute
    dict_offerDetailsAttr[key] = dict_detailsTableOfOffer[value]
KeyError: 'Parkování'
2021-02-12 23:02:50,162 - root - WARNING - garage was not grabbed.
Traceback (most recent call last):
  File "C:\Osobni\rApp\rApp\extractDataFromOfferFlow.py", line 122, in execute
    dict_offerDetailsAttr[key] = dict_detailsTableOfOffer[value]
KeyError: 'Garáž'
2021-02-12 23:02:50,162 - root - WARNING - transferToPersonalOwnership was not grabbed.
Traceback (most recent call last):
  File "C:\Osobni\rApp\rApp\extractDataFromOfferFlow.py", line 122, in execute
    dict_offerDetailsAttr[key] = dict_detailsTableOfOffer[value]
KeyError: 'Pøevod do OV'
2021-02-12 23:02:50,163 - root - WARNING - yearOfApproval was not grabbed.
Traceback (most recent call last):
  File "C:\Osobni\rApp\rApp\extractDataFromOfferFlow.py", line 122, in execute
    dict_offerDetailsAttr[key] = dict_detailsTableOfOffer[value]
KeyError: 'Rok kolaudace'
2021-02-12 23:02:50,163 - root - WARNING - gas was not grabbed.
Traceback (most recent call last):
  File "C:\Osobni\rApp\rApp\extractDataFromOfferFlow.py", line 139, in execute
    dict_offerDetailsAttr[key] = dict_detailsTableOfOffer[value][0]["value"]
KeyError: 'Plyn'
2021-02-12 23:02:50,163 - root - WARNING - culturalHeritageDistance was not grabbed.
Traceback (most recent call last):
  File "C:\Osobni\rApp\rApp\extractDataFromOfferFlow.py", line 179, in execute
    dict_offerDetailsAttr[key] = dict_poi[value]
KeyError: 'Kulturní památka'
2021-02-12 23:02:50,164 - root - WARNING - tramDistance was not grabbed.
Traceback (most recent call last):
  File "C:\Osobni\rApp\rApp\extractDataFromOfferFlow.py", line 179, in execute
    dict_offerDetailsAttr[key] = dict_poi[value]
KeyError: 'Tram'
2021-02-12 23:02:50,164 - root - WARNING - metroDistance was not grabbed.
Traceback (most recent call last):
  File "C:\Osobni\rApp\rApp\extractDataFromOfferFlow.py", line 179, in execute
    dict_offerDetailsAttr[key] = dict_poi[value]
KeyError: 'Metro'
2021-02-12 23:02:50,164 - root - WARNING - naturalAttractionDistance was not grabbed.
Traceback (most recent call last):
  File "C:\Osobni\rApp\rApp\extractDataFromOfferFlow.py", line 179, in execute
    dict_offerDetailsAttr[key] = dict_poi[value]
KeyError: 'Pøírodní zajímavost'
2021-02-12 23:02:50,164 - googleapiclient.discovery_cache - WARNING - file_cache is unavailable when using oauth2client >= 4.0.0 or google-auth
Traceback (most recent call last):
  File "C:\Users\pavel\AppData\Local\Programs\Python\Python37-32\lib\site-packages\googleapiclient\discovery_cache\file_cache.py", line 33, in <module>
    from oauth2client.contrib.locked_file import LockedFile
ModuleNotFoundError: No module named 'oauth2client.contrib.locked_file'

During handling of the above exception, another exception occurred:

Traceback (most recent call last):
  File "C:\Users\pavel\AppData\Local\Programs\Python\Python37-32\lib\site-packages\googleapiclient\discovery_cache\file_cache.py", line 37, in <module>
    from oauth2client.locked_file import LockedFile
ModuleNotFoundError: No module named 'oauth2client.locked_file'

During handling of the above exception, another exception occurred:

Traceback (most recent call last):
  File "C:\Users\pavel\AppData\Local\Programs\Python\Python37-32\lib\site-packages\googleapiclient\discovery_cache\__init__.py", line 44, in autodetect
    from . import file_cache
  File "C:\Users\pavel\AppData\Local\Programs\Python\Python37-32\lib\site-packages\googleapiclient\discovery_cache\file_cache.py", line 41, in <module>
    "file_cache is unavailable when using oauth2client >= 4.0.0 or google-auth"
ImportError: file_cache is unavailable when using oauth2client >= 4.0.0 or google-auth
2021-02-12 23:02:51,261 - root - WARNING - terraceSqMeter was not grabbed.
Traceback (most recent call last):
  File "C:\Osobni\rApp\rApp\extractDataFromOfferFlow.py", line 122, in execute
    dict_offerDetailsAttr[key] = dict_detailsTableOfOffer[value]
KeyError: 'Terasa'
2021-02-12 23:02:51,262 - root - WARNING - terrace was not grabbed.
Traceback (most recent call last):
  File "C:\Osobni\rApp\rApp\extractDataFromOfferFlow.py", line 122, in execute
    dict_offerDetailsAttr[key] = dict_detailsTableOfOffer[value]
KeyError: 'Terasa'
2021-02-12 23:02:51,262 - root - WARNING - priceNote was not grabbed.
Traceback (most recent call last):
  File "C:\Osobni\rApp\rApp\extractDataFromOfferFlow.py", line 122, in execute
    dict_offerDetailsAttr[key] = dict_detailsTableOfOffer[value]
KeyError: 'Poznámka k cenì'
2021-02-12 23:02:51,262 - root - WARNING - lift was not grabbed.
Traceback (most recent call last):
  File "C:\Osobni\rApp\rApp\extractDataFromOfferFlow.py", line 122, in execute
    dict_offerDetailsAttr[key] = dict_detailsTableOfOffer[value]
KeyError: 'Výtah'
2021-02-12 23:02:51,264 - root - WARNING - id was not grabbed.
Traceback (most recent call last):
  File "C:\Osobni\rApp\rApp\extractDataFromOfferFlow.py", line 122, in execute
    dict_offerDetailsAttr[key] = dict_detailsTableOfOffer[value]
KeyError: 'ID zakázky'
2021-02-12 23:02:51,264 - root - WARNING - energyPerformanceOfBuilding was not grabbed.
Traceback (most recent call last):
  File "C:\Osobni\rApp\rApp\extractDataFromOfferFlow.py", line 122, in execute
    dict_offerDetailsAttr[key] = dict_detailsTableOfOffer[value]
KeyError: 'Energetická nároènost budovy'
2021-02-12 23:02:51,264 - root - WARNING - barrieFree was not grabbed.
Traceback (most recent call last):
  File "C:\Osobni\rApp\rApp\extractDataFromOfferFlow.py", line 122, in execute
    dict_offerDetailsAttr[key] = dict_detailsTableOfOffer[value]
KeyError: 'Bezbariérový'
2021-02-12 23:02:51,265 - root - WARNING - parking was not grabbed.
Traceback (most recent call last):
  File "C:\Osobni\rApp\rApp\extractDataFromOfferFlow.py", line 122, in execute
    dict_offerDetailsAttr[key] = dict_detailsTableOfOffer[value]
KeyError: 'Parkování'
2021-02-12 23:02:51,265 - root - WARNING - garage was not grabbed.
Traceback (most recent call last):
  File "C:\Osobni\rApp\rApp\extractDataFromOfferFlow.py", line 122, in execute
    dict_offerDetailsAttr[key] = dict_detailsTableOfOffer[value]
KeyError: 'Garáž'
2021-02-12 23:02:51,265 - root - WARNING - equipped was not grabbed.
Traceback (most recent call last):
  File "C:\Osobni\rApp\rApp\extractDataFromOfferFlow.py", line 122, in execute
    dict_offerDetailsAttr[key] = dict_detailsTableOfOffer[value]
KeyError: 'Vybavení'
2021-02-12 23:02:51,265 - root - WARNING - transferToPersonalOwnership was not grabbed.
Traceback (most recent call last):
  File "C:\Osobni\rApp\rApp\extractDataFromOfferFlow.py", line 122, in execute
    dict_offerDetailsAttr[key] = dict_detailsTableOfOffer[value]
KeyError: 'Pøevod do OV'
2021-02-12 23:02:51,265 - root - WARNING - yearOfApproval was not grabbed.
Traceback (most recent call last):
  File "C:\Osobni\rApp\rApp\extractDataFromOfferFlow.py", line 122, in execute
    dict_offerDetailsAttr[key] = dict_detailsTableOfOffer[value]
KeyError: 'Rok kolaudace'
2021-02-12 23:02:51,265 - root - WARNING - transport was not grabbed.
Traceback (most recent call last):
  File "C:\Osobni\rApp\rApp\extractDataFromOfferFlow.py", line 139, in execute
    dict_offerDetailsAttr[key] = dict_detailsTableOfOffer[value][0]["value"]
KeyError: 'Doprava'
2021-02-12 23:02:51,265 - root - WARNING - gas was not grabbed.
Traceback (most recent call last):
  File "C:\Osobni\rApp\rApp\extractDataFromOfferFlow.py", line 139, in execute
    dict_offerDetailsAttr[key] = dict_detailsTableOfOffer[value][0]["value"]
KeyError: 'Plyn'
2021-02-12 23:02:51,265 - root - WARNING - electricity was not grabbed.
Traceback (most recent call last):
  File "C:\Osobni\rApp\rApp\extractDataFromOfferFlow.py", line 139, in execute
    dict_offerDetailsAttr[key] = dict_detailsTableOfOffer[value][0]["value"]
KeyError: 'Elektøina'
2021-02-12 23:02:51,265 - root - WARNING - culturalHeritageDistance was not grabbed.
Traceback (most recent call last):
  File "C:\Osobni\rApp\rApp\extractDataFromOfferFlow.py", line 179, in execute
    dict_offerDetailsAttr[key] = dict_poi[value]
KeyError: 'Kulturní památka'
2021-02-12 23:02:51,265 - root - WARNING - tramDistance was not grabbed.
Traceback (most recent call last):
  File "C:\Osobni\rApp\rApp\extractDataFromOfferFlow.py", line 179, in execute
    dict_offerDetailsAttr[key] = dict_poi[value]
KeyError: 'Tram'
2021-02-12 23:02:51,268 - root - WARNING - metroDistance was not grabbed.
Traceback (most recent call last):
  File "C:\Osobni\rApp\rApp\extractDataFromOfferFlow.py", line 179, in execute
    dict_offerDetailsAttr[key] = dict_poi[value]
KeyError: 'Metro'
2021-02-12 23:02:51,268 - root - WARNING - naturalAttractionDistance was not grabbed.
Traceback (most recent call last):
  File "C:\Osobni\rApp\rApp\extractDataFromOfferFlow.py", line 179, in execute
    dict_offerDetailsAttr[key] = dict_poi[value]
KeyError: 'Pøírodní zajímavost'
2021-02-12 23:02:51,271 - googleapiclient.discovery_cache - WARNING - file_cache is unavailable when using oauth2client >= 4.0.0 or google-auth
Traceback (most recent call last):
  File "C:\Users\pavel\AppData\Local\Programs\Python\Python37-32\lib\site-packages\googleapiclient\discovery_cache\file_cache.py", line 33, in <module>
    from oauth2client.contrib.locked_file import LockedFile
ModuleNotFoundError: No module named 'oauth2client.contrib.locked_file'

During handling of the above exception, another exception occurred:

Traceback (most recent call last):
  File "C:\Users\pavel\AppData\Local\Programs\Python\Python37-32\lib\site-packages\googleapiclient\discovery_cache\file_cache.py", line 37, in <module>
    from oauth2client.locked_file import LockedFile
ModuleNotFoundError: No module named 'oauth2client.locked_file'

During handling of the above exception, another exception occurred:

Traceback (most recent call last):
  File "C:\Users\pavel\AppData\Local\Programs\Python\Python37-32\lib\site-packages\googleapiclient\discovery_cache\__init__.py", line 44, in autodetect
    from . import file_cache
  File "C:\Users\pavel\AppData\Local\Programs\Python\Python37-32\lib\site-packages\googleapiclient\discovery_cache\file_cache.py", line 41, in <module>
    "file_cache is unavailable when using oauth2client >= 4.0.0 or google-auth"
ImportError: file_cache is unavailable when using oauth2client >= 4.0.0 or google-auth
2021-02-12 23:02:52,222 - root - WARNING - terraceSqMeter was not grabbed.
Traceback (most recent call last):
  File "C:\Osobni\rApp\rApp\extractDataFromOfferFlow.py", line 122, in execute
    dict_offerDetailsAttr[key] = dict_detailsTableOfOffer[value]
KeyError: 'Terasa'
2021-02-12 23:02:52,223 - root - WARNING - terrace was not grabbed.
Traceback (most recent call last):
  File "C:\Osobni\rApp\rApp\extractDataFromOfferFlow.py", line 122, in execute
    dict_offerDetailsAttr[key] = dict_detailsTableOfOffer[value]
KeyError: 'Terasa'
2021-02-12 23:02:52,223 - root - WARNING - cellarSqMeter was not grabbed.
Traceback (most recent call last):
  File "C:\Osobni\rApp\rApp\extractDataFromOfferFlow.py", line 122, in execute
    dict_offerDetailsAttr[key] = dict_detailsTableOfOffer[value]
KeyError: 'Sklep'
2021-02-12 23:02:52,223 - root - WARNING - cellar was not grabbed.
Traceback (most recent call last):
  File "C:\Osobni\rApp\rApp\extractDataFromOfferFlow.py", line 122, in execute
    dict_offerDetailsAttr[key] = dict_detailsTableOfOffer[value]
KeyError: 'Sklep'
2021-02-12 23:02:52,224 - root - WARNING - priceNote was not grabbed.
Traceback (most recent call last):
  File "C:\Osobni\rApp\rApp\extractDataFromOfferFlow.py", line 122, in execute
    dict_offerDetailsAttr[key] = dict_detailsTableOfOffer[value]
KeyError: 'Poznámka k cenì'
2021-02-12 23:02:52,224 - root - WARNING - lift was not grabbed.
Traceback (most recent call last):
  File "C:\Osobni\rApp\rApp\extractDataFromOfferFlow.py", line 122, in execute
    dict_offerDetailsAttr[key] = dict_detailsTableOfOffer[value]
KeyError: 'Výtah'
2021-02-12 23:02:52,224 - root - WARNING - idOrder was not grabbed.
Traceback (most recent call last):
  File "C:\Osobni\rApp\rApp\extractDataFromOfferFlow.py", line 122, in execute
    dict_offerDetailsAttr[key] = dict_detailsTableOfOffer[value]
KeyError: 'ID'
2021-02-12 23:02:52,224 - root - WARNING - barrieFree was not grabbed.
Traceback (most recent call last):
  File "C:\Osobni\rApp\rApp\extractDataFromOfferFlow.py", line 122, in execute
    dict_offerDetailsAttr[key] = dict_detailsTableOfOffer[value]
KeyError: 'Bezbariérový'
2021-02-12 23:02:52,224 - root - WARNING - parking was not grabbed.
Traceback (most recent call last):
  File "C:\Osobni\rApp\rApp\extractDataFromOfferFlow.py", line 122, in execute
    dict_offerDetailsAttr[key] = dict_detailsTableOfOffer[value]
KeyError: 'Parkování'
2021-02-12 23:02:52,224 - root - WARNING - garage was not grabbed.
Traceback (most recent call last):
  File "C:\Osobni\rApp\rApp\extractDataFromOfferFlow.py", line 122, in execute
    dict_offerDetailsAttr[key] = dict_detailsTableOfOffer[value]
KeyError: 'Garáž'
2021-02-12 23:02:52,224 - root - WARNING - transferToPersonalOwnership was not grabbed.
Traceback (most recent call last):
  File "C:\Osobni\rApp\rApp\extractDataFromOfferFlow.py", line 122, in execute
    dict_offerDetailsAttr[key] = dict_detailsTableOfOffer[value]
KeyError: 'Pøevod do OV'
2021-02-12 23:02:52,224 - root - WARNING - yearOfApproval was not grabbed.
Traceback (most recent call last):
  File "C:\Osobni\rApp\rApp\extractDataFromOfferFlow.py", line 122, in execute
    dict_offerDetailsAttr[key] = dict_detailsTableOfOffer[value]
KeyError: 'Rok kolaudace'
2021-02-12 23:02:52,224 - root - WARNING - transport was not grabbed.
Traceback (most recent call last):
  File "C:\Osobni\rApp\rApp\extractDataFromOfferFlow.py", line 139, in execute
    dict_offerDetailsAttr[key] = dict_detailsTableOfOffer[value][0]["value"]
KeyError: 'Doprava'
2021-02-12 23:02:52,224 - root - WARNING - water was not grabbed.
Traceback (most recent call last):
  File "C:\Osobni\rApp\rApp\extractDataFromOfferFlow.py", line 139, in execute
    dict_offerDetailsAttr[key] = dict_detailsTableOfOffer[value][0]["value"]
KeyError: 'Voda'
2021-02-12 23:02:52,224 - root - WARNING - gas was not grabbed.
Traceback (most recent call last):
  File "C:\Osobni\rApp\rApp\extractDataFromOfferFlow.py", line 139, in execute
    dict_offerDetailsAttr[key] = dict_detailsTableOfOffer[value][0]["value"]
KeyError: 'Plyn'
2021-02-12 23:02:52,224 - root - WARNING - heating was not grabbed.
Traceback (most recent call last):
  File "C:\Osobni\rApp\rApp\extractDataFromOfferFlow.py", line 139, in execute
    dict_offerDetailsAttr[key] = dict_detailsTableOfOffer[value][0]["value"]
KeyError: 'Topení'
2021-02-12 23:02:52,229 - root - WARNING - electricity was not grabbed.
Traceback (most recent call last):
  File "C:\Osobni\rApp\rApp\extractDataFromOfferFlow.py", line 139, in execute
    dict_offerDetailsAttr[key] = dict_detailsTableOfOffer[value][0]["value"]
KeyError: 'Elektøina'
2021-02-12 23:02:52,229 - root - WARNING - roads was not grabbed.
Traceback (most recent call last):
  File "C:\Osobni\rApp\rApp\extractDataFromOfferFlow.py", line 139, in execute
    dict_offerDetailsAttr[key] = dict_detailsTableOfOffer[value][0]["value"]
KeyError: 'Komunikace'
2021-02-12 23:02:52,229 - root - WARNING - culturalHeritageDistance was not grabbed.
Traceback (most recent call last):
  File "C:\Osobni\rApp\rApp\extractDataFromOfferFlow.py", line 179, in execute
    dict_offerDetailsAttr[key] = dict_poi[value]
KeyError: 'Kulturní památka'
2021-02-12 23:02:52,229 - root - WARNING - tramDistance was not grabbed.
Traceback (most recent call last):
  File "C:\Osobni\rApp\rApp\extractDataFromOfferFlow.py", line 179, in execute
    dict_offerDetailsAttr[key] = dict_poi[value]
KeyError: 'Tram'
2021-02-12 23:02:52,229 - root - WARNING - metroDistance was not grabbed.
Traceback (most recent call last):
  File "C:\Osobni\rApp\rApp\extractDataFromOfferFlow.py", line 179, in execute
    dict_offerDetailsAttr[key] = dict_poi[value]
KeyError: 'Metro'
2021-02-12 23:02:52,229 - root - WARNING - cinemaDistance was not grabbed.
Traceback (most recent call last):
  File "C:\Osobni\rApp\rApp\extractDataFromOfferFlow.py", line 179, in execute
    dict_offerDetailsAttr[key] = dict_poi[value]
KeyError: 'Kino'
2021-02-12 23:02:52,231 - root - WARNING - theaterDistance was not grabbed.
Traceback (most recent call last):
  File "C:\Osobni\rApp\rApp\extractDataFromOfferFlow.py", line 179, in execute
    dict_offerDetailsAttr[key] = dict_poi[value]
KeyError: 'Divadlo'
2021-02-12 23:02:52,231 - root - WARNING - storeDistance was not grabbed.
Traceback (most recent call last):
  File "C:\Osobni\rApp\rApp\extractDataFromOfferFlow.py", line 179, in execute
    dict_offerDetailsAttr[key] = dict_poi[value]
KeyError: 'Obchod'
2021-02-12 23:02:52,231 - root - WARNING - naturalAttractionDistance was not grabbed.
Traceback (most recent call last):
  File "C:\Osobni\rApp\rApp\extractDataFromOfferFlow.py", line 179, in execute
    dict_offerDetailsAttr[key] = dict_poi[value]
KeyError: 'Pøírodní zajímavost'
2021-02-12 23:02:52,234 - googleapiclient.discovery_cache - WARNING - file_cache is unavailable when using oauth2client >= 4.0.0 or google-auth
Traceback (most recent call last):
  File "C:\Users\pavel\AppData\Local\Programs\Python\Python37-32\lib\site-packages\googleapiclient\discovery_cache\file_cache.py", line 33, in <module>
    from oauth2client.contrib.locked_file import LockedFile
ModuleNotFoundError: No module named 'oauth2client.contrib.locked_file'

During handling of the above exception, another exception occurred:

Traceback (most recent call last):
  File "C:\Users\pavel\AppData\Local\Programs\Python\Python37-32\lib\site-packages\googleapiclient\discovery_cache\file_cache.py", line 37, in <module>
    from oauth2client.locked_file import LockedFile
ModuleNotFoundError: No module named 'oauth2client.locked_file'

During handling of the above exception, another exception occurred:

Traceback (most recent call last):
  File "C:\Users\pavel\AppData\Local\Programs\Python\Python37-32\lib\site-packages\googleapiclient\discovery_cache\__init__.py", line 44, in autodetect
    from . import file_cache
  File "C:\Users\pavel\AppData\Local\Programs\Python\Python37-32\lib\site-packages\googleapiclient\discovery_cache\file_cache.py", line 41, in <module>
    "file_cache is unavailable when using oauth2client >= 4.0.0 or google-auth"
ImportError: file_cache is unavailable when using oauth2client >= 4.0.0 or google-auth
2021-02-12 23:02:53,209 - root - WARNING - terraceSqMeter was not grabbed.
Traceback (most recent call last):
  File "C:\Osobni\rApp\rApp\extractDataFromOfferFlow.py", line 122, in execute
    dict_offerDetailsAttr[key] = dict_detailsTableOfOffer[value]
KeyError: 'Terasa'
2021-02-12 23:02:53,209 - root - WARNING - terrace was not grabbed.
Traceback (most recent call last):
  File "C:\Osobni\rApp\rApp\extractDataFromOfferFlow.py", line 122, in execute
    dict_offerDetailsAttr[key] = dict_detailsTableOfOffer[value]
KeyError: 'Terasa'
2021-02-12 23:02:53,210 - root - WARNING - idOrder was not grabbed.
Traceback (most recent call last):
  File "C:\Osobni\rApp\rApp\extractDataFromOfferFlow.py", line 122, in execute
    dict_offerDetailsAttr[key] = dict_detailsTableOfOffer[value]
KeyError: 'ID'
2021-02-12 23:02:53,210 - root - WARNING - barrieFree was not grabbed.
Traceback (most recent call last):
  File "C:\Osobni\rApp\rApp\extractDataFromOfferFlow.py", line 122, in execute
    dict_offerDetailsAttr[key] = dict_detailsTableOfOffer[value]
KeyError: 'Bezbariérový'
2021-02-12 23:02:53,210 - root - WARNING - garage was not grabbed.
Traceback (most recent call last):
  File "C:\Osobni\rApp\rApp\extractDataFromOfferFlow.py", line 122, in execute
    dict_offerDetailsAttr[key] = dict_detailsTableOfOffer[value]
KeyError: 'Garáž'
2021-02-12 23:02:53,211 - root - WARNING - transferToPersonalOwnership was not grabbed.
Traceback (most recent call last):
  File "C:\Osobni\rApp\rApp\extractDataFromOfferFlow.py", line 122, in execute
    dict_offerDetailsAttr[key] = dict_detailsTableOfOffer[value]
KeyError: 'Pøevod do OV'
2021-02-12 23:02:53,211 - root - WARNING - yearOfApproval was not grabbed.
Traceback (most recent call last):
  File "C:\Osobni\rApp\rApp\extractDataFromOfferFlow.py", line 122, in execute
    dict_offerDetailsAttr[key] = dict_detailsTableOfOffer[value]
KeyError: 'Rok kolaudace'
2021-02-12 23:02:53,211 - root - WARNING - gas was not grabbed.
Traceback (most recent call last):
  File "C:\Osobni\rApp\rApp\extractDataFromOfferFlow.py", line 139, in execute
    dict_offerDetailsAttr[key] = dict_detailsTableOfOffer[value][0]["value"]
KeyError: 'Plyn'
2021-02-12 23:02:53,212 - root - WARNING - roads was not grabbed.
Traceback (most recent call last):
  File "C:\Osobni\rApp\rApp\extractDataFromOfferFlow.py", line 139, in execute
    dict_offerDetailsAttr[key] = dict_detailsTableOfOffer[value][0]["value"]
KeyError: 'Komunikace'
2021-02-12 23:02:53,212 - root - WARNING - culturalHeritageDistance was not grabbed.
Traceback (most recent call last):
  File "C:\Osobni\rApp\rApp\extractDataFromOfferFlow.py", line 179, in execute
    dict_offerDetailsAttr[key] = dict_poi[value]
KeyError: 'Kulturní památka'
2021-02-12 23:02:53,212 - root - WARNING - tramDistance was not grabbed.
Traceback (most recent call last):
  File "C:\Osobni\rApp\rApp\extractDataFromOfferFlow.py", line 179, in execute
    dict_offerDetailsAttr[key] = dict_poi[value]
KeyError: 'Tram'
2021-02-12 23:02:53,213 - root - WARNING - metroDistance was not grabbed.
Traceback (most recent call last):
  File "C:\Osobni\rApp\rApp\extractDataFromOfferFlow.py", line 179, in execute
    dict_offerDetailsAttr[key] = dict_poi[value]
KeyError: 'Metro'
2021-02-12 23:02:53,213 - root - WARNING - theaterDistance was not grabbed.
Traceback (most recent call last):
  File "C:\Osobni\rApp\rApp\extractDataFromOfferFlow.py", line 179, in execute
    dict_offerDetailsAttr[key] = dict_poi[value]
KeyError: 'Divadlo'
2021-02-12 23:02:53,213 - root - WARNING - naturalAttractionDistance was not grabbed.
Traceback (most recent call last):
  File "C:\Osobni\rApp\rApp\extractDataFromOfferFlow.py", line 179, in execute
    dict_offerDetailsAttr[key] = dict_poi[value]
KeyError: 'Pøírodní zajímavost'
2021-02-12 23:02:53,213 - googleapiclient.discovery_cache - WARNING - file_cache is unavailable when using oauth2client >= 4.0.0 or google-auth
Traceback (most recent call last):
  File "C:\Users\pavel\AppData\Local\Programs\Python\Python37-32\lib\site-packages\googleapiclient\discovery_cache\file_cache.py", line 33, in <module>
    from oauth2client.contrib.locked_file import LockedFile
ModuleNotFoundError: No module named 'oauth2client.contrib.locked_file'

During handling of the above exception, another exception occurred:

Traceback (most recent call last):
  File "C:\Users\pavel\AppData\Local\Programs\Python\Python37-32\lib\site-packages\googleapiclient\discovery_cache\file_cache.py", line 37, in <module>
    from oauth2client.locked_file import LockedFile
ModuleNotFoundError: No module named 'oauth2client.locked_file'

During handling of the above exception, another exception occurred:

Traceback (most recent call last):
  File "C:\Users\pavel\AppData\Local\Programs\Python\Python37-32\lib\site-packages\googleapiclient\discovery_cache\__init__.py", line 44, in autodetect
    from . import file_cache
  File "C:\Users\pavel\AppData\Local\Programs\Python\Python37-32\lib\site-packages\googleapiclient\discovery_cache\file_cache.py", line 41, in <module>
    "file_cache is unavailable when using oauth2client >= 4.0.0 or google-auth"
ImportError: file_cache is unavailable when using oauth2client >= 4.0.0 or google-auth
2021-02-12 23:02:54,131 - root - WARNING - terraceSqMeter was not grabbed.
Traceback (most recent call last):
  File "C:\Osobni\rApp\rApp\extractDataFromOfferFlow.py", line 122, in execute
    dict_offerDetailsAttr[key] = dict_detailsTableOfOffer[value]
KeyError: 'Terasa'
2021-02-12 23:02:54,132 - root - WARNING - terrace was not grabbed.
Traceback (most recent call last):
  File "C:\Osobni\rApp\rApp\extractDataFromOfferFlow.py", line 122, in execute
    dict_offerDetailsAttr[key] = dict_detailsTableOfOffer[value]
KeyError: 'Terasa'
2021-02-12 23:02:54,132 - root - WARNING - idOrder was not grabbed.
Traceback (most recent call last):
  File "C:\Osobni\rApp\rApp\extractDataFromOfferFlow.py", line 122, in execute
    dict_offerDetailsAttr[key] = dict_detailsTableOfOffer[value]
KeyError: 'ID'
2021-02-12 23:02:54,132 - root - WARNING - barrieFree was not grabbed.
Traceback (most recent call last):
  File "C:\Osobni\rApp\rApp\extractDataFromOfferFlow.py", line 122, in execute
    dict_offerDetailsAttr[key] = dict_detailsTableOfOffer[value]
KeyError: 'Bezbariérový'
2021-02-12 23:02:54,133 - root - WARNING - garage was not grabbed.
Traceback (most recent call last):
  File "C:\Osobni\rApp\rApp\extractDataFromOfferFlow.py", line 122, in execute
    dict_offerDetailsAttr[key] = dict_detailsTableOfOffer[value]
KeyError: 'Garáž'
2021-02-12 23:02:54,133 - root - WARNING - equipped was not grabbed.
Traceback (most recent call last):
  File "C:\Osobni\rApp\rApp\extractDataFromOfferFlow.py", line 122, in execute
    dict_offerDetailsAttr[key] = dict_detailsTableOfOffer[value]
KeyError: 'Vybavení'
2021-02-12 23:02:54,133 - root - WARNING - transferToPersonalOwnership was not grabbed.
Traceback (most recent call last):
  File "C:\Osobni\rApp\rApp\extractDataFromOfferFlow.py", line 122, in execute
    dict_offerDetailsAttr[key] = dict_detailsTableOfOffer[value]
KeyError: 'Pøevod do OV'
2021-02-12 23:02:54,133 - root - WARNING - yearOfApproval was not grabbed.
Traceback (most recent call last):
  File "C:\Osobni\rApp\rApp\extractDataFromOfferFlow.py", line 122, in execute
    dict_offerDetailsAttr[key] = dict_detailsTableOfOffer[value]
KeyError: 'Rok kolaudace'
2021-02-12 23:02:54,133 - root - WARNING - culturalHeritageDistance was not grabbed.
Traceback (most recent call last):
  File "C:\Osobni\rApp\rApp\extractDataFromOfferFlow.py", line 179, in execute
    dict_offerDetailsAttr[key] = dict_poi[value]
KeyError: 'Kulturní památka'
2021-02-12 23:02:54,133 - root - WARNING - tramDistance was not grabbed.
Traceback (most recent call last):
  File "C:\Osobni\rApp\rApp\extractDataFromOfferFlow.py", line 179, in execute
    dict_offerDetailsAttr[key] = dict_poi[value]
KeyError: 'Tram'
2021-02-12 23:02:54,133 - root - WARNING - metroDistance was not grabbed.
Traceback (most recent call last):
  File "C:\Osobni\rApp\rApp\extractDataFromOfferFlow.py", line 179, in execute
    dict_offerDetailsAttr[key] = dict_poi[value]
KeyError: 'Metro'
2021-02-12 23:02:54,133 - root - WARNING - naturalAttractionDistance was not grabbed.
Traceback (most recent call last):
  File "C:\Osobni\rApp\rApp\extractDataFromOfferFlow.py", line 179, in execute
    dict_offerDetailsAttr[key] = dict_poi[value]
KeyError: 'Pøírodní zajímavost'
2021-02-12 23:02:54,139 - googleapiclient.discovery_cache - WARNING - file_cache is unavailable when using oauth2client >= 4.0.0 or google-auth
Traceback (most recent call last):
  File "C:\Users\pavel\AppData\Local\Programs\Python\Python37-32\lib\site-packages\googleapiclient\discovery_cache\file_cache.py", line 33, in <module>
    from oauth2client.contrib.locked_file import LockedFile
ModuleNotFoundError: No module named 'oauth2client.contrib.locked_file'

During handling of the above exception, another exception occurred:

Traceback (most recent call last):
  File "C:\Users\pavel\AppData\Local\Programs\Python\Python37-32\lib\site-packages\googleapiclient\discovery_cache\file_cache.py", line 37, in <module>
    from oauth2client.locked_file import LockedFile
ModuleNotFoundError: No module named 'oauth2client.locked_file'

During handling of the above exception, another exception occurred:

Traceback (most recent call last):
  File "C:\Users\pavel\AppData\Local\Programs\Python\Python37-32\lib\site-packages\googleapiclient\discovery_cache\__init__.py", line 44, in autodetect
    from . import file_cache
  File "C:\Users\pavel\AppData\Local\Programs\Python\Python37-32\lib\site-packages\googleapiclient\discovery_cache\file_cache.py", line 41, in <module>
    "file_cache is unavailable when using oauth2client >= 4.0.0 or google-auth"
ImportError: file_cache is unavailable when using oauth2client >= 4.0.0 or google-auth
2021-02-12 23:02:55,043 - root - WARNING - terraceSqMeter was not grabbed.
Traceback (most recent call last):
  File "C:\Osobni\rApp\rApp\extractDataFromOfferFlow.py", line 122, in execute
    dict_offerDetailsAttr[key] = dict_detailsTableOfOffer[value]
KeyError: 'Terasa'
2021-02-12 23:02:55,043 - root - WARNING - terrace was not grabbed.
Traceback (most recent call last):
  File "C:\Osobni\rApp\rApp\extractDataFromOfferFlow.py", line 122, in execute
    dict_offerDetailsAttr[key] = dict_detailsTableOfOffer[value]
KeyError: 'Terasa'
2021-02-12 23:02:55,043 - root - WARNING - priceNote was not grabbed.
Traceback (most recent call last):
  File "C:\Osobni\rApp\rApp\extractDataFromOfferFlow.py", line 122, in execute
    dict_offerDetailsAttr[key] = dict_detailsTableOfOffer[value]
KeyError: 'Poznámka k cenì'
2021-02-12 23:02:55,043 - root - WARNING - location was not grabbed.
Traceback (most recent call last):
  File "C:\Osobni\rApp\rApp\extractDataFromOfferFlow.py", line 122, in execute
    dict_offerDetailsAttr[key] = dict_detailsTableOfOffer[value]
KeyError: 'Umístìní objektu'
2021-02-12 23:02:55,043 - root - WARNING - idOrder was not grabbed.
Traceback (most recent call last):
  File "C:\Osobni\rApp\rApp\extractDataFromOfferFlow.py", line 122, in execute
    dict_offerDetailsAttr[key] = dict_detailsTableOfOffer[value]
KeyError: 'ID'
2021-02-12 23:02:55,043 - root - WARNING - barrieFree was not grabbed.
Traceback (most recent call last):
  File "C:\Osobni\rApp\rApp\extractDataFromOfferFlow.py", line 122, in execute
    dict_offerDetailsAttr[key] = dict_detailsTableOfOffer[value]
KeyError: 'Bezbariérový'
2021-02-12 23:02:55,043 - root - WARNING - parking was not grabbed.
Traceback (most recent call last):
  File "C:\Osobni\rApp\rApp\extractDataFromOfferFlow.py", line 122, in execute
    dict_offerDetailsAttr[key] = dict_detailsTableOfOffer[value]
KeyError: 'Parkování'
2021-02-12 23:02:55,043 - root - WARNING - garage was not grabbed.
Traceback (most recent call last):
  File "C:\Osobni\rApp\rApp\extractDataFromOfferFlow.py", line 122, in execute
    dict_offerDetailsAttr[key] = dict_detailsTableOfOffer[value]
KeyError: 'Garáž'
2021-02-12 23:02:55,043 - root - WARNING - transferToPersonalOwnership was not grabbed.
Traceback (most recent call last):
  File "C:\Osobni\rApp\rApp\extractDataFromOfferFlow.py", line 122, in execute
    dict_offerDetailsAttr[key] = dict_detailsTableOfOffer[value]
KeyError: 'Pøevod do OV'
2021-02-12 23:02:55,043 - root - WARNING - yearOfApproval was not grabbed.
Traceback (most recent call last):
  File "C:\Osobni\rApp\rApp\extractDataFromOfferFlow.py", line 122, in execute
    dict_offerDetailsAttr[key] = dict_detailsTableOfOffer[value]
KeyError: 'Rok kolaudace'
2021-02-12 23:02:55,043 - root - WARNING - gas was not grabbed.
Traceback (most recent call last):
  File "C:\Osobni\rApp\rApp\extractDataFromOfferFlow.py", line 139, in execute
    dict_offerDetailsAttr[key] = dict_detailsTableOfOffer[value][0]["value"]
KeyError: 'Plyn'
2021-02-12 23:02:55,048 - root - WARNING - culturalHeritageDistance was not grabbed.
Traceback (most recent call last):
  File "C:\Osobni\rApp\rApp\extractDataFromOfferFlow.py", line 179, in execute
    dict_offerDetailsAttr[key] = dict_poi[value]
KeyError: 'Kulturní památka'
2021-02-12 23:02:55,048 - root - WARNING - tramDistance was not grabbed.
Traceback (most recent call last):
  File "C:\Osobni\rApp\rApp\extractDataFromOfferFlow.py", line 179, in execute
    dict_offerDetailsAttr[key] = dict_poi[value]
KeyError: 'Tram'
2021-02-12 23:02:55,048 - root - WARNING - metroDistance was not grabbed.
Traceback (most recent call last):
  File "C:\Osobni\rApp\rApp\extractDataFromOfferFlow.py", line 179, in execute
    dict_offerDetailsAttr[key] = dict_poi[value]
KeyError: 'Metro'
2021-02-12 23:02:55,048 - root - WARNING - theaterDistance was not grabbed.
Traceback (most recent call last):
  File "C:\Osobni\rApp\rApp\extractDataFromOfferFlow.py", line 179, in execute
    dict_offerDetailsAttr[key] = dict_poi[value]
KeyError: 'Divadlo'
2021-02-12 23:02:55,048 - root - WARNING - veterinaryDistance was not grabbed.
Traceback (most recent call last):
  File "C:\Osobni\rApp\rApp\extractDataFromOfferFlow.py", line 179, in execute
    dict_offerDetailsAttr[key] = dict_poi[value]
KeyError: 'Veterináø'
2021-02-12 23:02:55,048 - root - WARNING - naturalAttractionDistance was not grabbed.
Traceback (most recent call last):
  File "C:\Osobni\rApp\rApp\extractDataFromOfferFlow.py", line 179, in execute
    dict_offerDetailsAttr[key] = dict_poi[value]
KeyError: 'Pøírodní zajímavost'
2021-02-12 23:02:55,053 - googleapiclient.discovery_cache - WARNING - file_cache is unavailable when using oauth2client >= 4.0.0 or google-auth
Traceback (most recent call last):
  File "C:\Users\pavel\AppData\Local\Programs\Python\Python37-32\lib\site-packages\googleapiclient\discovery_cache\file_cache.py", line 33, in <module>
    from oauth2client.contrib.locked_file import LockedFile
ModuleNotFoundError: No module named 'oauth2client.contrib.locked_file'

During handling of the above exception, another exception occurred:

Traceback (most recent call last):
  File "C:\Users\pavel\AppData\Local\Programs\Python\Python37-32\lib\site-packages\googleapiclient\discovery_cache\file_cache.py", line 37, in <module>
    from oauth2client.locked_file import LockedFile
ModuleNotFoundError: No module named 'oauth2client.locked_file'

During handling of the above exception, another exception occurred:

Traceback (most recent call last):
  File "C:\Users\pavel\AppData\Local\Programs\Python\Python37-32\lib\site-packages\googleapiclient\discovery_cache\__init__.py", line 44, in autodetect
    from . import file_cache
  File "C:\Users\pavel\AppData\Local\Programs\Python\Python37-32\lib\site-packages\googleapiclient\discovery_cache\file_cache.py", line 41, in <module>
    "file_cache is unavailable when using oauth2client >= 4.0.0 or google-auth"
ImportError: file_cache is unavailable when using oauth2client >= 4.0.0 or google-auth
